Workbook
Name МТ: [1]Раб!$O$10:$O$21

Sheet Общие свединия 
A1: № | B1: Общие свединия опредприяти
A2: 1 | B2: Полное наименование предприятия | C2: ООО « Hаmkor nur savdo»
A3: 2 | B3: Юридический адрес | C3: Ташкентская область, Ахангаран, терр-я промзоны, Б6
A4: 3 | B4: ФИО руководителя | C4: Хамидов Абдулахад миркомилович
A5: 4 | B5: Форма собственности | C5: ООО
A6: 5 | B6: Отрасль экономики | C6: Дубление и выделка кожи; выделка и окраска меха
A7: 6 | B7: ФИО ответственного за энергетику | C7: MIRZAAXMEDOV RUSTAM XABIBULLAYEVICH
A8: 7 | B8: Контактный телефон | C8: 974709981
A9: 8 | B9: Электронная почта | C9: ulugbek.x026@gmail.com
A10: 9 | B10: Численность персонала (чел.) | C10: 142
A11: 10 | B11: Год основания | C11: 9 сентября 2004 г.
A12: 11 | B12: Площадь здания (м²) | C12: 8725
A13: 12 | B13: Объем здания (м³) | C13: =(25*101.5*8)+(63*62*12)+(30*60*8)+(15*15*3)+(12*40*3) -> 83687

Sheet Свод по зданиям
A1: Здание
A2: 1. Общие сведения
A3: 1.1 | B3: Наименование объекта | C3: ='Общие свединия '!C2 -> ООО « Hаmkor nur savdo»
A4: 1.2 | B4: Адрес | C4: ='Общие свединия '!C3 -> Ташкентская область, Ахангаран, терр-я промзоны, Б6
A5: 1.3 | B5: Тип здания | C5: Нежилое
A6: 1.4 | B6: Год ввода в эксплуатацию | C6: 2019
A7: 1.5 | B7: Общая площадь здания, м² | C7: ='Общие свединия '!C12 -> 8725
A8: 1.6 | B8: Отапливаемый объем, м³ | C8: =(15*15*3)+(12*40*3) -> 2115
A9: 1.7 | B9: Количество этажей | C9: 1
A10: 2. Сведения о теплопотерях
A11: 2.1 | B11: Расчетные теплопотери, Гкал/год | C11: 30.13
A12: 2.2 | B12: Фактические теплопотери, Гкал/год | C12: 0.064
A13: 2.3 | B13: Удельное потребление тепловой энергии, Гкал/м²·год | C13: 3.2e-05
A14: 2.4 | B14: Максимальное и относительное потребление энергии на отопление здания за градусо-день | C14: 34.21 | D14: кВт
A15: 3. Энергетические характеристики
A16: 3.1 | B16: Удельное энергопотребление, кВт·ч/м²·год | C16: =1902*0.1*24*140 -> 639072
A17: 3.2 | B17: Годовое потребление тепловой энергии, Гкал | C17: =C16*0.00086 -> 549.60192
A18: 3.3 | B18: Годовое потребление электроэнергии, тыс. кВт·ч | C18: 1307.109 | D18: 2022-2023-2024 год средное
A19: 3.4 | B19: Годовое потребление газа, тыс. м³ | C19: 455.549 | D19: 2022-2023-2024 год средное
A20: 3.5 | B20: Энергетический класс здания | C20: А
A21: 4. Энергопотребление по системам
A22: 4.1 | B22: Система | C22: Ед. изм. | D22: Потребление в год
A23: 4.2 | B23: Отопление | C23: Гкал | D23: =C17*0.9 -> 494.64173
A24: 4.3 | B24: ГВС | C24: Гкал | D24: =C17*0.1 -> 54.960192
A25: 4.4 | B25: Вентиляция и кондиционирование | C25: тыс. кВт·ч | D25: 4.087
A26: 4.5 | B26: Освещение | C26: тыс. кВт·ч | D26: 15.873
A27: 4.6 | B27: Прочие нужды | C27: тыс. кВт·ч | D27: 10.8
A28: 5. Выводы и рекомендации
A29: 5.1 | B29: Оценка фактического энергопотребления
A30: 5.2 | B30: Выявленные теплопотери
A31: 5.3 | B31: Рекомендации по снижению энергопотребления

Sheet Ограждающие к-я
B1: Ограждающие конструкций
B2: 1. Теплопотери через ограждающие конструкции
A3: 1 | B3: Конструкция | C3: Площадь, м² | D3: Сопротивление теплопередаче R, м²·°C/Вт * | E3: Температурная разность, °C | F3: Q = S * ΔT / R, Вт
A4: 2 | B4: Наружная стена | C4: 0 | D4: 2.8 | E4: 25 | F4: =C4*E4/D4 -> 0
A5: 3 | B5: Отстекления | C5: 0 | D5: 0.6 | E5: 1 | F5: =C5*E5/D5 -> 0
A6: 4 | B6: Крыша | C6: 0 | D6: 4.5 | E6: 25 | F6: =C6*E6/D6 -> 0
A7: 5 | B7: Пол по грунту | C7: 0 | D7: 3.5 | E7: 5 | F7: =C7*E7/D7 -> 0
B8: *Нормативные : R, м²·°C/Вт по ГСОП
B11: ГСОП (°С·сут/год) | C11: Стены (м²·°С/Вт) | D11: Кровля (м²·°С/Вт) | E11: Остекление (м²·°С/Вт)
B12: 2000 | C12: 2.1 | D12: 3.2 | E12: 0.3
B13: 4000 | C13: 2.8 | D13: 4.2 | E13: 0.45
B14: 6000 | C14: 3.5 | D14: 5.2 | E14: 0.6
B17: 2. Энергетическая эффективность системы отопления
B18: Параметр | C18: Значение | D18: Единица измерения | E18: Комментарий
A19: 1 | B19: Установленная мощность котлов | C19: 100 | D19: кВт
A20: 2 | B20: Фактическое теплопотребление за отопит. период | C20: 450 | D20: Гкал
A21: 3 | B21: Площадь здания | C21: 2000 | D21: м²
A22: 4 | B22: Удельное потребление тепла | D22: кВт·ч/м² | E22: ≈ 522 кВт·ч/м²
A23: 5 | B23: КПД системы отопления | C23: 85 | D23: % | E23: Паспортное значение котла
A24: 6 | B24: Энергетический класс | C24: C | D24: - | E24: По классификатору
D27: АБК
A28: № | B28: Конструкция | C28: Материал | D28: Толщина, м | E28: λ (Вт/м·°C) | F28: R = δ/λ, (м²·°C)/Вт | G28: Нормативное Rтр | H28: Площадь, м² | I28: ΔT, °C | J28: Q = S·ΔT/R, Вт | K28: потерия ВТ м2 | L28: норма потерия Вт м2 | M28: Котегория
A29: 1 | B29: Стена | C29: Шлака блок | D29: 0.38 | E29: 0.76 | F29: =D29/E29 -> 0.5 | G29: 2.8 | H29: 280.8 | I29: 16 | J29: =H29*I29/F29 -> 8985.6 | K29: =J33/H33 -> 36.649057 | L29: 96 | M29: А
A30: 2 | B30: Окно | C30: Стеклопакет | D30: 0.03 | E30: 0.8 | F30: =D30/E30 -> 0.0375 | G30: 0.8 | H30: 31.2 | I30: 16 | J30: =H30*I30/F30 -> 13312
A31: 3 | B31: Крыша | C31: Плита и Профнастил | D31: 0.2 | E31: 0.3 | F31: =D31/E31 -> 0.66666667 | G31: 4.7 | H31: =12*40 -> 480 | I31: 16 | J31: =H31*I31/F31 -> 11520
A32: 4 | B32: Пол | C32: Бетон | D32: 0.15 | E32: 0.8 | F32: =D32/E32 -> 0.1875 | G32: 3.4 | H32: =12*40 -> 480 | I32: 5 | J32: =H32*I32/F32 -> 12800
H33: =SUM(H29:H32) -> 1272 | J33: =SUM(J29:J32) -> 46617.6
J34: =J33/1000 -> 46.6176
D36: Админстративная
A37: № | B37: Конструкция | C37: Материал | D37: Толщина, м | E37: λ (Вт/м·°C) | F37: R = δ/λ, (м²·°C)/Вт | G37: Нормативное Rтр | H37: Площадь, м² | I37: ΔT, °C | J37: Q = S·ΔT/R, Вт | K37: потерия ВТ м2 | L37: норма потерия Вт м2 | M37: Котегория
A38: 1 | B38: Стена | C38: Шлака блок | D38: 0.38 | E38: 0.76 | F38: =D38/E38 -> 0.5 | G38: 2.8 | H38: 162 | I38: 20 | J38: =H38*I38/F38 -> 6480 | K38: =J42/H42 -> 45.761905 | L38: 96 | M38: А
A39: 2 | B39: Окно | C39: Стеклопакет | D39: 0.03 | E39: 0.8 | F39: =D39/E39 -> 0.0375 | G39: 0.8 | H39: 18 | I39: 20 | J39: =H39*I39/F39 -> 9600
A40: 3 | B40: Крыша | C40: Плита и Профнастил | D40: 0.2 | E40: 0.3 | F40: =D40/E40 -> 0.66666667 | G40: 4.7 | H40: =15*15 -> 225 | I40: 20 | J40: =H40*I40/F40 -> 6750
A41: 4 | B41: Пол | C41: Бетон | D41: 0.15 | E41: 0.8 | F41: =D41/E41 -> 0.1875 | G41: 3.4 | H41: =15*15 -> 225 | I41: 5 | J41: =H41*I41/F41 -> 6000
H42: =SUM(H38:H41) -> 630 | J42: =SUM(J38:J41) -> 28830
J43: =J42/1000 -> 28.83

Sheet Электроэнергия
A1: Система электроснабжения 1.Общие данные
A4: № | B4: Параметр | C4: Ед.изм | D4: Значения | E4: Норматив/Требования | F4: Примечания
A5: 1.1 | B5: Поставщик | C5: - | E5: Сети АО"Худудэлектртармоклари"
A6: 1.2 | B6: Категория надежности | C6: - | D6: II | E6: ( I,II,III по ПУЭ)
A7: 1.3 | B7: Напрежения входящей сети | C7: кВ | D7: 6 | E7: ГОСТ
A8: 1.4 | B8: Макс.мощность подключения | C8: кВт/кВт | D8: 800 | E8: по техусловиям(ТУ)
A9: 1.5 | B9: Средесуточное потребления | C9: кВт*ч | D9: 5102
A10: 1.6 | B10: Годовой потребления | C10: тыс.кВт*ч | D10: 1307109.4 | E10: 2022-2023-2024 год средное
A11: 2. Оборудования и инфростуктура
A12: № | B12: Параметры | C12: Ед.изм. | D12: Кол-во/Мощность | E12: Техническое состаяние | F12: Срок эксплуатаций
A13: 2.1 | B13: Трансформатор | C13: шт | D13: 630 кВа 1000 кВа | E13: удв
A14: 2.2 | B14: Распридительный щиты (РЩ) | C14: шт | D14: 4 | E14: удв
A15: 2.3 | B15: ККУ(кандицаторный установки р-э) | C15: шт | D15: 125 квар 150 квар | E15: удв
A16: 2.4 | B16: Генераторы резервные | C16: шт | D16: -
A17: 2.5 | B17: ИБП ( источники без перебойного питания) | C17: шт | D17: -
A18: 2.6 | B18: Кабельные линии | C18: м | D18: 475 | E18: удв
A19: 2.7 | B19: Электродвигатели (2строка наличие регулируемого эелктропривода) | C19: шт | D19: 60 | E19: удв
C20: шт
A21: 2.8 | B21: Система учета | C21: шт | D21: 2 | E21: удв
A22: 3. Системы КИПиА
A23: № | B23: Параметры | C23: Тип прибора | D23: Дата выпуска | E23: Дата ГОСТ поверки | F23: Примечания
A24: 3.1 | B24: Коммерчиский учёта | C24: ТЕ73 SG-1-0 19036783 ТЕ73 SG-1-0 19087231 | D24: 22,10,2024 | E24: 22,10,2028
A25: 3.2 | B25: Контроль напрежения | C25: Вольтметр
A26: 3.3 | B26: Котроль тока | C26: Амперметр
A27: 3.4 | B27: Автаматические выкльючатели
A28: 4. Анализ расходов
A30: № | B30: Параметр | C30: Ед.изм. | D30: Значения | E30: Период (мес./год)
A31: 4.1 | B31: Тариф на э-э | C31: сум/кВт | D31: Дифф.
A32: 4.2 | B32: Затраты | C32: сум. | D32: 8.1901072e+08 | E32: 2023 год
A33: 4.3 | B33: Затраты на э-э (месяц) | C33: кВт/ч | D33: 118821.2 | E33: средное за 2023 год
A34: 4.4 | B34: Затраты на э-э (год) | C34: кВт/ч | D34: 1425854.4 | E34: 2023 год
A35: 4.5 | B35: Техногические потери | C35: кВт/ч | D35: =D34*0.05 -> 71292.723 | E35: 2023 год
A36: 4.6 | B36: Прочие потери (аварий, утечки, ППР) | C36: кВт/ч
A37: 5. Эксплуатация
A38: № | B38: Параметр | C38: Дата | D38: Вид работ | E38: Исполнитель | F38: Стоимость
A39: 5.1 | B39: Последнее ТО . ТП | C39: 26,11,2023 | D39: Испытания трансформатора | E39: Elektro-tehnik labaratoriya
A40: 5.2 | B40: Испытания на сопртивления изоляций кабеля
A41: 5.3 | B41: Ремонтные работы
A42: 5.4 | B42: Замена КИП
A43: 5.5 | B43: Замена оборудования
...

Sheet Газ
A1: Система газснабжения 1. Общая част
A4: № | B4: Параметр | C4: Ед.изм | D4: Значения | E4: Норматив/Требования | F4: Примечания
A5: 1.1 | B5: Источник газа | C5: м3 | E5: Поставщик АО "Худудгаз"
A6: 1.2 | B6: Проектная мошность подключения | C6: м3/ч | D6: 785000 | E6: По техусловиям (ТУ)
A7: 1.3 | B7: Рабочее давления в сети | C7: кг*см2 | D7: 1 | E7: ГОСТ,ТУ поставщика
A8: 1.4 | B8: Макс.часавой расход | C8: м3/ч | D8: 395.92 | E8: По техусловиям (ТУ) | F8: Пиковая ногрузка
A9: 1.5 | B9: Средний суточный расход (зимний) | C9: м3/сут | D9: 1547.87
A10: 1.6 | B10: Средний суточный расход (летний) | C10: м3/сут | D10: 790.4
A11: 1.7 | B11: Годовой потребления | C11: тыс.м3 | D11: 455.5493 | E11: 2022-2023-2024 год средное
A12: 2. Оборудования и инфростуктура
A13: № | B13: Параметры | C13: Ед.изм. | D13: Кол-во/Мощность | E13: Техническое состаяние
A14: 2.1 | B14: Газовые котлы | C14: шт. | D14: 6 | E14: удв
A15: 2.2 | B15: Мощность котлов | C15: кВт | D15: 3771
A16: 2.3 | B16: Теплогенераторы | C16: шт. | D16: -
A17: 2.4 | B17: ПГ-4х | C17: шт. | D17: 1 | E17: удв
A18: 2.5 | B18: В/К | C18: шт. | D18: 2 | E18: удв
A19: 2.6 | B19: ГРП(газорегуляторный пункт) | C19: шт. | D19: 4 | E19: не удв
A20: 2.7 | B20: Запорные арматуры | C20: шт. | D20: 12 | E20: не удв
A21: 3. Системы КИП
A22: № | B22: Параметры | C22: Тип прибора | D22: Дата выпуска | E22: Дата ГОСТ поверки | F22: Погрешность
A23: 3.1 | B23: Коммерчиский узел учёта (счётчик) | C23: Смарт Г25 000072 Флоугаз 03021 | D23: 2022 | E23: 2024 г 13 август 2023 г 6 декабр
A24: 3.2 | B24: Контроль давления | C24: Манометр
A25: 3.3 | B25: Газоанализаторы (CH4,CO) | C25: -
A26: 4. Анализ расходов
A28: № | B28: Параметр | C28: Ед.изм. | D28: Значения | E28: Период (мес./год)
A29: 4.1 | B29: Тариф на газ | C29: сум/м3 | D29: 1500 | E29: 2024 год
A30: 4.2 | B30: Затраты | C30: сум. | D30: 625731000 | E30: 2024 год
A31: 4.3 | B31: Затраты на газ (месяц) | C31: м3 | D31: 64177.54 | E31: средное 2024 год
A32: 4.4 | B32: Затраты на газ (год) | C32: м3 | D32: 455.5493 | E32: 2022-2023-2024 год средное
A33: 4.5 | B33: Техногические потери | C33: м3 | D33: =14.4*365*4 -> 21024 | E33: в год
A34: 4.6 | B34: Прочие потери (аварий, утечки, ППР) | C34: м3 | D34: -
A35: 5. Эксплуатация
A36: № | B36: Параметр | C36: Дата | D36: Вид работ | E36: Исполнитель | F36: Стоимость
A37: 5.1 | B37: Последнее ТО газового оборудования | C37: - | D37: -
A38: 5.2 | B38: Опресовка газопроводов на герметичность | C38: - | D38: -
A39: 5.3 | B39: Ремонтные работы | C39: - | D39: -
A40: 5.4 | B40: Замена КИП | C40: 2022 год сентябрь | D40: Замена счётчика принс на Смарт Г25
A41: 5.5 | B41: Замена оборудования
A42: 6.Система безопастности
A44: № | B44: Параметр | C44: Тип прибора | D44: Состаяние (да/нет) | E44: Дата поверки | F44: Ответственый
...

Sheet Вода
A1: Система водааснабжения
A3: 1.Общие данные
A4: № | B4: Параметр | C4: Ед.изм | D4: Значения | E4: Норматив/Требования | F4: Примечания
A5: 1.1 | B5: Потребление воды из собственных источников водоснабжения и от сторонних организаций скважина | C5: м3 | E5: Поставщик АО "Сувсоз" Скважина
A6: 1.2 | B6: Проектная мошность подключения | D6: 10,61 570,1 | E6: По техусловиям (ТУ) | F6: в сутки по КЭН
A7: 1.3 | B7: Рабочее давления в сети | C7: МПа(бар) | D7: 2 | E7: ГОСТ,ТУ поставщика
A8: 1.4 | B8: Средний суточный расход (зимний) | C8: м3/сут | D8: 654,7 | E8: 2022 год
A9: 1.5 | B9: Средний суточный расход (летний) | C9: м3/сут | D9: 770,93 | E9: 2022 год
A10: 1.6 | B10: Годовой потребления | C10: тыс.м3 | D10: 142,058 | E10: 2022-2023-2024 год средное
A11: 2. Оборудования и инфростуктура
A12: № | B12: Параметры | C12: Ед.изм. | D12: Кол-во/Мощность | E12: Техническое состаяние
A13: 1.1 | B13: Системы водопроводов | C13: п/м
A14: 1.2 | B14: Насосы | C14: шт. | D14: 3
A15: 1.3 | B15: Системы очистных соружений и рециркуляции | C15: шт. | D15: 1 | F15: Очисное соруужения не полная
A16: 1.4 | B16: Система отведения сточных вод | C16: шт. | F16: Канализация
A17: 3. Системы КИП
A18: № | B18: Параметры | C18: Тип прибора | D18: Дата выпуска | E18: Дата ГОСТ поверки | F18: Погрешность
A19: 1.1 | B19: Коммерчиский узел учёта (счётчик) | C19: Байлан UW6 24622 | E19: 16 ноябр 2022 г
A20: 1.2 | B20: Контроль давления | C20: Манометр
A21: 4. Анализ расходов
A23: № | B23: Параметр | C23: Ед.изм. | D23: Значения | E23: Период (мес./год)
A24: 1.1 | B24: Тариф | C24: сум/м3 | D24: 9000 | E24: 2 октябр 2024 | F24: Канализация 2000 сум/м3
A25: 1.2 | B25: Затраты | C25: сум. | D25: 245649432 | E25: 2024 год
A26: 1.3 | B26: Затраты на воду(месяц) | C26: м3. | D26: 9122.91 | E26: средное 2024 год
A27: 1.4 | B27: Затраты на воду (год) | C27: м3. | D27: 110994 | E27: 2024 год
A28: 1.5 | B28: Техногические потери | C28: м3 | D28: -
A29: 1.6 | B29: Прочие потери (аварий, утечки, ППР) | C29: м3 | D29: -

Sheet Расходы на ед.пр
A1: 2024 год
A2: № | B2: Энергоноситель | C2: Ед. изм. | D2: Годовой расход | E2: Удельный расход на 1 м2 продукции | F2: Источник данных | G2: Комментарий
A3: 1 | B3: Электроэнергия | C3: кВт·ч | D3: 511787.11 | E3: 0.86 | F3: Счётчик / баланс | G3: В том числе по цехам
A4: 2 | B4: Природный газ | C4: м³ | D4: 417154 | E4: 0.34 | F4: Газовый счётчик / баланс | G4: Для сушки, обогрева
A5: 3 | B5: Вода (техническая) | C5: м³ | D5: 110994 | E5: 0.095 | F5: Водомер | G5: Для охлаждения, санитарии
A6: 4 | B6: Дизельное топливо | C6: л | D6: - | E6: - | F6: Журнал расхода / накладные | G6: При наличии резервных ДГУ
A7: 5 | B7: Уголь / мазут / др. | C7: кг / л | D7: - | E7: - | F7: Отчёт / журнал | G7: При наличии
A8: 6 | B8: Прочее (по необходимости) | C8: - | D8: - | E8: -
A11: Объём выпушенний продукции
A12: Год | B12: Кожа дм2 | C12: Дублённая кожа шт | D12: Спилок кг | E12: Примечание
A13: 2022 | B13: 23019859 | C13: 381341 | D13: 18345 | E13: -
A14: 2023 | B14: 21085528 | C14: 291619 | D14: 229600 | E14: -
A15: 2024 | B15: 11566508 | C15: 115890 | D15: 10540 | E15: -
A16: 2025 | B16: 1515348 | C16: - | D16: 241833 | E16: Январь-апрель
A18: Удельный расход на ед. продукта
A19: Электроэнергия
A20: год | B20: Итого | C20: Хоз. быт нужд | D20: Потеря | E20: Производство | F20: продукт м2 | G20: кВт/м2
A21: 2022 | B21: 1355516.8 | C21: 30760 | D21: 67775.84 | E21: 1256980.9 | F21: 2353442 | G21: 0.53410321
A22: 2023 | B22: 1425854.4 | C22: 30760 | D22: 71292.72 | E22: 1323801.7 | F22: 2160674.7 | G22: 0.61267979
A23: 2024 | B23: 949964 | C23: 30760 | D23: 47498.2 | E23: 871705.8 | F23: 1169293.8 | G23: 0.74549767
A25: Газ
A26: год | B26: Производство | C26: Продукт м2 | D26: м3/м2
A27: 2022 | B27: 325530.52 | C27: 2353442 | D27: 0.138
A28: 2023 | B28: 421187.52 | C28: 2160674.7 | D28: 0.195 | M28: =0.086*10 -> 0.86
A29: 2024 | B29: 399059.52 | C29: 1169293.8 | D29: 0.341
A31: Вода
A32: Год | B32: м3 | C32: Продукт м2 | D32: м3/м2
A33: 2022 | B33: 162686 | C33: 2353442 | D33: 0.069
A34: 2023 | B34: 152495 | C34: 2160674.7 | D34: 0.071
A35: 2024 | B35: 110994 | C35: 1169293.8 | D35: 0.095

Sheet котель
A1: Наименование | B1: Время | C1: °C Тдг | D1: % CO₂ | E1: % qAnet | F1: λ | G1: % O₂ | H1: ппм СO | I1: ппм нСО | J1: °C Тдг | K1: % уКПД | L1: Пасп. КПД % | M1: Отклонения от КПД | N1: Темп. ок.сред С | O1: мбар Тяга | R1: Мошност оборудование КВт | S1: Для природного газа | T1: Для угля | U1: Коифицент | V1: КПД % для газа | W1: КПд для угля
A2: пара/катёл | B2: 45794.488 | C2: 156.4 | D2: 0.91 | E2: 50 | F2: 13.13 | G2: 19.4 | H2: 1 | I2: - | J2: 156.4 | K2: 50 | L2: - | N2: 41 | O2: -0.01 | R2: 25 | S2: 80.5 | T2: 71.5 | U2: 0.044 | V2: 81.6 | W2: 72.6
A3: пара/катёл | B3: 45794.528 | C3: 222.1 | D3: 2.27 | E3: 31.5 | F3: 5.25 | G3: 17 | H3: 886 | I3: 3371 | J3: 222.1 | K3: 68.5 | L3: - | N3: 41 | O3: -0.09 | R3: 50 | S3: 80.5 | T3: 71.5 | U3: 0.044 | V3: 82.7 | W3: 73.7
A4: воду нагревательный | B4: 45794.578 | C4: 169.6 | D4: 3.17 | E4: 16.2 | F4: 3.75 | G4: 15.4 | H4: 0 | I4: 26 | J4: 169.6 | K4: 83.8 | L4: - | N4: 41 | O4: -0.01 | R4: 75 | S4: 80.5 | T4: 71.5 | U4: 0.044 | V4: 83.8 | W4: 74.8
R5: 100 | S5: 80.5 | T5: 71.5 | U5: 0.044 | V5: 84.9 | W5: 75.9
R6: Вышее 100 КВТ мошносты нижная планка 84,9 %
R7: основание
A8: Абк | R8: ШНК 2.01.18-24
A9: Фактический расчёта расхода газа | G9: Нормативний расчёта расхода газа | R9: Глава 6 Нормативние показатели энергоэффективности приборов пункт 27
A10: № | B10: Параметр | C10: Обозначение | D10: Значение | E10: Ед. изм. | G10: № | H10: Параметр | I10: Обозначение | J10: Значение | K10: Ед. изм.
A11: 1 | B11: Отапливаемая площадь | C11: S | D11: ='Ограждающие к-я'!H33 -> 1272 | E11: м² | G11: 1 | H11: Отапливаемая площадь | I11: S | J11: =D11 -> 1272 | K11: м²
A12: 2 | B12: Удельные теплопотери | C12: qуд | D12: 36.7 | E12: Вт/м² | G12: 2 | H12: Удельные теплопотери | I12: qуд | J12: 36.7 | K12: Вт/м²
A13: 3 | B13: Разность температур (tв - tн) | C13: Δt | D13: 23 | E13: °C | G13: 3 | H13: Разность температур (tв - tн) | I13: Δt | J13: 23 | K13: °C
A14: 4 | B14: Продолжительность отопления | C14: Zотопл | D14: 140 | E14: суток | G14: 4 | H14: Продолжительность отопления | I14: Zотопл | J14: 140 | K14: суток
A15: 5 | B15: КПД котла | C15: η | D15: 0.85 | E15: % | G15: 5 | H15: КПД котла | I15: η | J15: 0.85 | K15: %
A16: 6 | B16: Теплотворная способность газа | C16: Qг | D16: 8 | E16: кВт·ч/м³ | G16: 6 | H16: Теплотворная способность газа | I16: Qг | J16: 8 | K16: кВт·ч/м³
A17: 7 | B17: Теплопотери Qпот | D17: =D11*D12*D13 -> 1073695.2 | E17: Вт | G17: 7 | H17: Теплопотери Qпот | J17: =J11*J12*J13 -> 1073695.2 | K17: Вт
A18: 8 | B18: Потребность в тепле Qгод | D18: 26.88 | E18: кВт·ч | G18: 8 | H18: Потребность в тепле Qгод | J18: 26.88 | K18: кВт·ч
A19: 9 | B19: Расход газа Vг | D19: =D17/(D15*D14) -> 9022.6487 | E19: м³ | G19: 9 | H19: Расход газа Vг | J19: =J17/(J15*J14) -> 9022.6487 | K19: м³
A20: 10 | B20: Расход на ед пл.д/год | D20: =D19/D11 -> 7.0932773 | E20: м² | G20: 10 | H20: Расход на ед пл.д/год | J20: =J19/J11 -> 7.0932773 | K20: м²
A21: Расчёт расхода газа с учётом на объёма помещения | G21: Расчёт расхода газа с учётом на объёма помещения
A22: № | B22: Параметр | C22: Обозначение | D22: Значение | E22: Ед. изм. | G22: № | H22: Параметр | I22: Обозначение | J22: Значение | K22: Ед. изм.
A23: 1 | B23: Отапливаемая площадь | C23: S | D23: =D11 -> 1272 | E23: м² | G23: 1 | H23: Отапливаемая площадь | I23: S | J23: =J11 -> 1272 | K23: м²
A24: 2 | B24: Высота потолков | C24: H | D24: 3 | E24: м | G24: 2 | H24: Высота потолков | I24: H | J24: 3 | K24: м
A25: 3 | B25: Объём помещения | C25: V | D25: =D23*D24 -> 3816 | E25: м³ | G25: 3 | H25: Объём помещения | I25: V | J25: =J23*J24 -> 3816 | K25: м³
A26: 4 | B26: Удельные теплопотери | C26: qуд | D26: =D12/6 -> 6.1166667 | E26: Вт/м³·°C | G26: 4 | H26: Удельные теплопотери | I26: qуд | J26: =D26 -> 6.1166667 | K26: Вт/м³·°C
A27: 5 | B27: Разность температур (tв - tн) | C27: Δt | D27: 23 | E27: °C | G27: 5 | H27: Разность температур (tв - tн) | I27: Δt | J27: 23 | K27: °C
A28: 6 | B28: Продолжительность отопления | C28: Zотопл | D28: 140 | E28: суток | G28: 6 | H28: Продолжительность отопления | I28: Zотопл | J28: 140 | K28: суток
A29: 7 | B29: КПД котла | C29: η | D29: 0.85 | E29: % | G29: 7 | H29: КПД котла | I29: η | J29: 0.85 | K29: %
A30: 8 | B30: Теплотворная способность газа | C30: Qг | D30: 8 | E30: кВт·ч/м³ | G30: 8 | H30: Теплотворная способность газа | I30: Qг | J30: 8 | K30: кВт·ч/м³
A31: 9 | B31: Теплопотери Qпот | D31: =D25*D26*D27 -> 536847.6 | E31: Вт | G31: 9 | H31: Теплопотери Qпот | J31: =J25*J26*J27 -> 536847.6 | K31: Вт
A32: 10 | B32: Потребность в тепле Qгод | D32: =D30*24*D28/1000 -> 26.88 | E32: кВт·ч | G32: 10 | H32: Потребность в тепле Qгод | J32: =J30*24*J28/1000 -> 26.88 | K32: кВт·ч
A33: 11 | B33: Расход газа Vг | D33: =D31/(D29*D28) -> 4511.3244 | E33: м³ | G33: 11 | H33: Расход газа Vг | J33: =J31/(J29*J28) -> 4511.3244 | K33: м³
A34: 12 | B34: Расход на ед.об/год | D34: =D33/D25 -> 1.1822129 | E34: м³ | G34: 12 | H34: Расход на ед.об/год | J34: =J33/J25 -> 1.1822129 | K34: м³
B36: Нормы расхода | D36: Фактический | E36: Отклонения %
A37: 1 | B37: м² | C37: 7,1 | D37: 7.1 | E37: 0
A38: 2 | B38: м³ | C38: 1,2 | D38: 1.2 | E38: 0
A39: Потенциал экономии | C39: =D19-J19 -> 0
A41: Админстативное
A42: Фактический расчёта расхода газа | G42: Нормативний расчёта расхода газа
...

Sheet ФЭС
A1: Фотоэлектрической станции (ФЭС) 1. Общая част
A3: 1.1 | B3: Наименование объекта
A4: 1.2 | B4: Адрес установки
A5: 1.3 | B5: Тип ФЭС | C5: автономная / сетевая / гибридная
A6: 1.4 | B6: Дата ввода в эксплуатацию
A7: 1.5 | B7: Проектная организация
A8: 1.6 | B8: Монтажная организация
A9: 2. Основные технические характеристики
A10: Параметр | C10: Значение | D10: Ед. изм.
A11: 2.1 | B11: Установленная мощность | D11: кВт
A12: 2.2 | B12: Тип и марка солнечных панелей
A13: 2.3 | B13: Кол-во модулей | D13: шт
A14: 2.4 | B14: Ориентация панелей (азимут, угол наклона) | D14: градусы
A15: 2.5 | B15: Тип инвертора
A16: 2.6 | B16: КПД солнечных модулей | D16: %
A17: 2.7 | B17: КПД инвертора | D17: %
A18: 2.8 | B18: Наличие накопителей энергии | C18: да / нет
A19: 2.9 | B19: Емкость накопителей (если есть) | D19: кВт·ч
A20: 2.10 | B20: 3. Производственные характеристики
A21: 2.11 | B21: Среднегодовая выработка электроэнергии | D21: кВт·ч/год
A22: 2.12 | B22: Удельная выработка | D22: кВт·ч/кВт
A23: 2.13 | B23: График суточной и сезонной выработки | C23: (прилагается в виде диаграммы)
A24: 4. Результаты энергоаудита / оценки эффективности
A25: 4.1 | B25: Фактический коэффициент производительности (PR)
A26: 4.2 | B26: Потери по компонентам | C26: (засорение, затенение, инвертор и др.)
A27: 4.3 | B27: Соответствие нормативам и стандартам
A28: 4.4 | B28: Энергосбережение / эффект от использования ФЭС
A29: 4.5 | B29: Замещение потребления из сети | D29: кВт·ч
A30: 4.6 | B30: Снижение выбросов CO₂ | D30: т/год
A31: 5. Выводы и рекомендации
A32: 5.1 | B32: Общее состояние системы
A33: 5.2 | B33: Потенциал повышения эффективности
A34: 5.3 | B34: Рекомендации по эксплуатации и обслуживанию
A35: Приложения | C35: Схема, фото, паспорта, расчеты и графики

Sheet Кондиционирования
A1: 1. Общие сведения
A2: 1 | B2: Наименование объекта: | C2: ='Общие свединия '!C2 -> ООО « Hаmkor nur savdo»
A3: 1.2 | B3: Тип здания: | C3: ='Свод по зданиям'!C5 -> Нежилое
A4: 1.3 | B4: Назначение помещения: | C4: АБК и Админстративная
A5: 2. Технические характеристики системы кондиционирования
A6: 2.1 | B6: Тип системы: | C6: Сплит кондиционер
A7: 2.2 | B7: Производитель и модель: | C7: Артел
A8: 2.3 | B8: Год выпуска/ввода в эксплуатацию:
A9: 2.4 | B9: Холодопроизводительность (кВт): | C9: =(6*3.75)+5.05+2.69 -> 30.24
A10: 2.5 | B10: Теплопроизводительность (если предусмотрено): | C10: =(6*4.07)+5.42+3.22 -> 33.06
A11: 2.6 | B11: Потребляемая мощность (кВт): | C11: =(6*1.11)+1.6+0.89 -> 9.15
A12: 2.7 | B12: Класс энергоэффективности | C12: А+
A13: 2.8 | B13: Тип хладагента: | C13: R 410 A фрион
A14: 2.9 | B14: Состояние оборудования: | C14: удв
A15: 3. Характеристика эксплуатации
A16: 3.1 | B16: Режим работы системы: | C16: при необходимости в зависимосты от разници температур
A17: 3.2 | B17: Среднегодовая загрузка (% от номинальной мощности): | C17: 0.73
A18: 3.3 | B18: Сезонность работы: | C18: Летний
A19: 3.4 | B19: Система управления: | C19: Встроинний термодатчик
A20: 3.5 | B20: Наличие системы рекуперации: | C20: нет
A21: 4. Потребление энергии
A22: 4.1 | B22: Фактическое потребление электроэнергии (за год), кВт·ч: | C22: =C11*0.73*153*4 -> 4087.854
A23: 4.2 | B23: Удельное потребление энергии на 1 м² обслуживаемой площади, кВт·ч/м²: | C23: =C22/1635.1 -> 2.5000636
A24: 4.3 | B24: Сравнение с нормативными значениями:
A25: 4.4 | B25: Оценка энергоэффективности:
A26: 5. Теплотехнический анализ помещений
A27: 5.1 | B27: Объём кондиционируемых помещений (м³): | C27: =1635.1*3 -> 4905.3
A28: 5.2 | B28: Теплопритоки от оборудования, людей, солнечной радиации (Вт): | C28: Не нормируемая
A29: 5.3 | B29: Необходимая холодопроизводительность: | C29: Не нормируемая
A30: 5.4 | B30: Фактическая обеспеченность холодом (%): | C30: 0.73
A31: 6. Выводы и рекомендации
A32: 6.1 | B32: Общие выводы об эффективности работы системы кондиционирования: | C32: удв
A33: 6.2 | B33: Наличие и причины перерасхода энергии (если выявлены): | C33: -
A34: 6.3 | B34: Рекомендации по улучшению энергоэффективности: | C34: -
A35: 7. Приложения
A36: 7.1 | B36: Копии технических паспортов оборудования
A37: 7.2 | B37: Планы помещений с указанием кондиционируемых зон
A38: 7.3 | B38: Диаграммы потребления энергии
A39: 7.4 | B39: Фотофиксация оборудования
A40: 7.5 | B40: Сертификаты энергоэффективности (если есть)

Sheet Вентиляция 
A2: Вентиляция 1. Общие сведения
A3: 1.1 | B3: Наименование объекта: | C3: ='Общие свединия '!C2 -> ООО « Hаmkor nur savdo»
A4: 1.2 | B4: Тип здания: | C4: ='Свод по зданиям'!C5 -> Нежилое
A5: 1.3 | B5: Назначение помещения: | C5: производственное
A6: 2. Технические характеристики системы вентиляции
A7: 2.1 | B7: Тип системы: (естественная, механическая, приточная, вытяжная, приточно-вытяжная) | C7: естесвенная
A8: 2.2 | B8: Производитель и модель оборудования:
A9: 2.3 | B9: Год выпуска/ввода в эксплуатацию:
A10: 2.4 | B10: Производительность по воздуху (м³/ч):
A11: 2.5 | B11: Потребляемая мощность вентустановки (кВт):
A12: 2.6 | B12: КПД вентилятора (%):
A13: 2.7 | B13: Наличие калорифера/охладителя воздуха (тип, мощность):
A14: 2.8 | B14: Тип системы автоматики и управления:
A15: 2.9 | B15: Состояние оборудования:
B16: 3. Характеристика эксплуатации
A17: 3.1 | B17: Режим работы системы: (часы в сутки, дни в неделю)
A18: 3.2 | B18: Сезонность работы:
A19: 3.3 | B19: Наличие системы рекуперации тепла: (да/нет, тип)
A20: 3.4 | B20: Уровень шума (дБ):
A21: 3.5 | B21: Эффективность воздухообмена (кол-во обменов в час):
B22: 4. Потребление энергии
A23: 4.1 | B23: Фактическое потребление электроэнергии (за год), кВт·ч:
A24: 4.2 | B24: Удельное потребление энергии на 1 м² обслуживаемой площади, кВт·ч/м²:
A25: 4.3 | B25: Сравнение с нормативными значениями:
A26: 4.4 | B26: Оценка энергоэффективности:
B27: 5. Теплотехнический анализ
A28: 5.1 | B28: Расчётные теплопотери при вентиляции (Вт):
A29: 5.2 | B29: Эффективность теплоутилизации (если есть рекуператор), %:
A30: 5.3 | B30: Необходимая тепловая мощность для нагрева воздуха:
A31: 5.4 | B31: Фактическое соответствие потребностям (%):
B32: 6. Выводы и рекомендации
A33: 6.1 | B33: Общие выводы об эффективности работы системы вентиляции:
A34: 6.2 | B34: Наличие и причины перерасхода энергии (если выявлены):
A35: 6.3 | B35: Рекомендации по улучшению энергоэффективности:
B36: 7. Приложения
A37: 7.1 | B37: Копии технических паспортов оборудования
A38: 7.2 | B38: Планы помещений с указанием вентиляционных зон
A39: 7.3 | B39: Диаграммы потребления энергии
A40: 7.4 | B40: Фотофиксация оборудования
A41: 7.5 | B41: Сертификаты энергоэффективности (если есть)

Sheet Отвод п-с
A1: 1. Общие сведения
A2: 1.1 | B2: Наименование объекта: | C2: ='Свод по зданиям'!C3 -> ООО « Hаmkor nur savdo»
A3: 1.2 | B3: Тип здания: | C3: ='Свод по зданиям'!C5 -> Нежилое
A4: 1.3 | B4: Назначение помещения: | C4: котелная
A5: 1.4 | B5: Дата составления:
A6: 2. Технические характеристики системы отвода продуктов сгорания
A7: 2.1 | B7: Тип системы: (естественная тяга, принудительная, комбинированная) | C7: Принудительная
A8: 2.2 | B8: Тип и марка дымохода/вентилятора: | C8: В комплекте с котлом
A9: 2.3 | B9: Год выпуска/ввода в эксплуатацию:
A10: 2.4 | B10: Высота и диаметр дымохода (м/мм): | C10: 8-10 м / 2 мм
A11: 2.5 | B11: Материал изготовления: | C11: жестянка
A12: 2.6 | B12: Температура отходящих газов (°C): | C12: 156,4 222,1 169,6
A13: 2.7 | B13: Максимальная производительность по газу/воздуху (м³/ч): | C13: 115м3 газ воздух 1150м3 / 165 м3 газ 1650 м3 воздух / 8,2 газ 82 м3 воздух
A14: 2.8 | B14: Потери давления в системе (Па):
A15: 2.9 | B15: Состояние оборудования и каналов: | C15: не удв
A16: 3. Характеристика эксплуатации
A17: 3.1 | B17: Режим работы системы (часы в сутки, дни в неделю):
A18: 3.2 | B18: Тип подключенного оборудования (котлы, горелки и т.д.):
A19: 3.3 | B19: Температурный режим эксплуатации:
A20: 3.4 | B20: Наличие систем контроля тяги и загазованности:
A21: 3.5 | B21: Обслуживание и частота очистки:
A22: 4. Потребление энергии (если есть электровентиляторы)
A23: 4.1 | B23: Потребляемая мощность вентилятора (кВт): | C23: 0,7 1 0,3
A24: 4.2 | B24: Фактическое годовое потребление электроэнергии (кВт·ч): | C24: 2520 3600 1080
A25: 4.3 | B25: Сравнение с нормативными значениями:
A26: 4.4 | B26: Оценка энергоэффективности:
A27: 5. Технический анализ
A28: 5.1 | B28: Расчётная тяга (Па):
A29: 5.2 | B29: Фактическая тяга (Па):
A30: 5.3 | B30: Потери тепла через дымоход (Вт):
A31: 5.4 | B31: Эффективность использования тепла сгорания (%):
A32: 6. Выводы и рекомендации
A33: 6.1 | B33: Общие выводы об эффективности работы системы:
A34: 6.2 | B34: Наличие и причины перерасхода энергии (если выявлены):
A35: 6.3 | B35: Рекомендации по улучшению энергоэффективности и безопасности:
A36: 7. Приложения
A37: 7.1 | B37: Копии технических паспортов оборудования
A38: 7.2 | B38: Схемы подключения и разводки каналов
A39: 7.3 | B39: Фотофиксация оборудования и каналов
A40: 7.4 | B40: Отчёты по газоанализу (если проводились)
...

Sheet Холодильник
A1: № | B1: Раздел | C1: Показатель | D1: Описание / Значение | E1: нагрузка (кВт·ч)
A2: 1 | B2: Оборудование | C2: Тип оборудования
A3: 2 | C3: Производитель / модель
A4: 3 | C4: Мощность компрессора (кВт)
A5: 4 | C5: Год выпуска
A6: 5 | C6: Тип хладагента
A7: 6 | C7: Температура кипения (°C)
A8: 7 | C8: Температура конденсации (°C)
A9: 8 | C9: Холодопроизводительность (кВт)
A10: 9 | B10: Энергетические параметры | C10: Суточное потребление электроэнергии (кВт·ч)
A11: 10 | C11: Годовое потребление электроэнергии (кВт·ч)
A12: 11 | C12: Коэффициент энергоэффективности (COP)
A13: 12 | C13: Удельное энергопотребление (кВт·ч/кВт холода)
A14: 13 | C14: Фактическая нагрузка (%)
A15: 14 | C15: Уровень потерь в трубопроводах (%)
A16: 15 | C16: Коэффициент использования мощности
A17: 16 | B17: Сравнение с эталоном | C17: Нормативное значение COP (по ISO/EN)
A18: 17 | C18: Фактическое значение COP
A19: 18 | C19: Эталонное оборудование (модель)
A20: 19 | C20: Класс энергоэффективности (A-G)
A21: 20 | B21: Рекомендации | C21: Улучшение теплоизоляции
A22: 21 | C22: Установка частотного преобразователя
A23: 22 | C23: Оптимизация графика загрузки
A24: 23 | C24: Техническое обслуживание
A25: 24 | C25: Замена на более эффективное оборудование

Sheet значения
A1: Тепловая мощность измеряется в гигакаллориях (Гкал) или мегаваттах (МВт). 1 Гкал/час — это 40 кубометров воды (40 м3/час), нагретые на 25 градусов Цельсия (25˚С) за один час. 1 Гкал = 1.163 МВт

Sheet мероприятия 
A1: № | B1: Мероприятие | C1: Затраты (сум) | D1: Годовая экономия (сум) | E1: Годовая экономия энерго ресурсах | F1: Срок окупаемости (лет) | G1: Срок выполнение | H1: Отвественний
A2: 1 | B2: ФЭС, (50 кВт) | C2: 400000000 | D2: 49140000 | E2: 54600 квт/г | F2: =C2/D2 -> 8.1400081
A3: 4 | B3: Охладители, воздухообмен | C3: 432114336 | I3: =50*8000000 -> 400000000 | K3: =50*0.7*6*260 -> 54600
A4: 7 | B4: Внедрение ИСО 50001 | C4: 50000000 | D4: 6000000 | F4: =C4/D4 -> 8.3333333 | K4: =K3*900 -> 49140000
A5: 8 | B5: Заменить ГРП + опрессовка газопровода | C5: 100000000 | D5: 15000000 | F5: =C5/D5 -> 6.6666667
A6: 9 | B6: Аккумулятор на 2мвт | C6: 20800000000 | D6: 1007500000 | F6: =C6/D6 -> 20.645161
A7: 10 | B7: Внедрить систему технологического учёта энергоресурсов
A8: 11 | B8: Воздухонагреватель | C8: 93172965 | D8: 19845000 | F8: =C8/D8 -> 4.6950348
A9: 12 | B9: Ввести эксплуатационный паспорт на автотранспорты
A10: 13 | B10: Ввести эксплуатационный паспорти по всем инженерным коммуникациям
