Workbook

Sheet Sheet1
B1: D A S T U R I
B2: 1. Dastur quyidagi hujjatlar asosida ishlab chiqilgan:
B3: Vazirlar Mahkamasining 2024 yil 19 oktyabrdagi “Yoqilg‘i-energetika resurslari iste’molchilarini hamda bino va inshootlarni energiya iste’molini energiya auditidan o‘tkazish tartiblarini belgilash to‘g‘risida”gi 690-sonli qarori;
B4: O‘zbekiston Respublikasining 2024 yil 7 avgustda qabul qilingan “Energiya tejash, undan oqilona foydalanish va energiya samaradorligini oshirish to‘g‘risida”gi 940-sonli Qonuni;
B5: O‘zbekistan Respublikasi Prezidentining 2019 yil 22 avgustdagi "Iqtisodiyot tarmoqlari va ijtimoiy sohaning energiya samaradorligini oshirish, energiya tejovchi texnologiyalarni joriy etish va qayta tiklanuvchi energiya manbalarini rivojlantirishning tezkor chora-tadbirlari to‘g‘risida"gi PQ-4422-son qaror;
A6: 1 | B6: O‘zbekiston Respublikasi Vazirlar Mahkamasining 2024 yil 31-maydagi “Elektr energiyasi va tabiiy gazdan foydalanish qoidalarini tasdiqlash to‘g‘risida”gi 319-sonli qarori;
A7: 2 | B7: (joylashgan manzili, uning identifikatsiya raqami va IFUD kodi)shaklidagi korxonasining energiya xo‘jaligi ob’yektlarida davriy energetika tekshiruvi (energoaudit) o‘tkazish to‘g‘risidagi shartnoma;
A8: 3 | B8: 1.1. Energiya auditidan o‘tkazish dasturining amal qilish muddati O‘zenergoinspeksiya tomonidan tasdiqlangan kundan boshlab dastlabki va davriy energiya auditidan o‘tkazishda bir yildan ko‘p bo‘lmagan hamda ekspress energiya auditidan ikki oydan ko‘p bo‘lmagan muddatga teng bo‘ladi.
A9: 4 | B9: 1.2. Yiliga besh yuz va undan ortiq tonna shartli yoqilg‘ini va (yoki) ikki yuz ellik va undan ortiq tonna motor yoqilg‘isini sarflaydigan yoqilg‘i-energetika resurslari iste’molchilari tomonidan belgilangan muddatlarda majburiy energetika tekshiruvlarini o‘tkazmaslik yoki ular tomonidan majburiy energetika tekshiruvlari natijasida belgilangan chora-tadbirlarni bajarmaslik - o‘rtacha oylik energiya iste’moli qiymatining uch foizi miqdorida jarima solishga sabab bo‘ladi
A10: 5 | B10: 2. Energetika tekshiruvi (energoaudit) o‘tkazishda quyidagilar o‘rganiladi:
A11: 6 | B11: Elektr ta’minoti:
A12: 7 | B12: elektr iste’moli rejimlari va elektr balansini tuzish;
A13: 8 | B13: elektr qabul qilgichlarning parametrlarini tekshirish va o‘lchash;
A14: 9 | B14: sexlarni bug‘ bilan ta’minlash ichki tizimining bug‘-kondensat balansini tuzish;
A15: 10 | B15: kondensatni manbaga qaytarish;
A16: 11 | B16: Yoqilg‘i energiya resurslari (keyingi o‘rinda YoER deb yuritiladi) iste’molchisining tuzilmasi va bo‘linmalardagi energiya iste’moli tavsifi;
A17: 12 | B17: energiya resurslari turlari bo‘yicha xususiy energiya balanslari;
... A121: 116 | B121: 4.1. Energiya auditi natijasi bo‘yicha hisobot va energetika pasporti O‘zenergoinspeksiyaning hududiy boshqarmalari tomonidan belgilangan tartibda qabul qilinmagunga qadar iste’molchida energiya auditi tamomlangan deb hisoblanmaydi.

Sheet Узел учета 
J1: Таблица 1
B2: Пункты учёта | C2: Вид учёта мощности электроэнергии (активная, реактивная) | E2: Место установки измерительных трансформаторов | G2: Коэффициент учёта | H2: Дата пломбировки | I2: Дата пломбировки поставщика | J2: Примечание
C3: P | D3: Q | E3: TT | F3: КT
C4: кВт·ч | D4: кВАр·ч
B5: Трёхфазый счётчик ЕХ518 124200393818 | C5: 4950000 | D5: 1825000 | E5: 1200/5 | F5: 0.4 | G5: 240 | H5: 12.2024 | I5: 12.2024 | J5: ПС «Каракамиш» 35/6 кВ
B6: Трёхфазый счётчик ЕХ518 124200507111 | E6: 1200/6 | F6: 0.4 | G6: 240 | H6: 12.2024 | I6: 12.2024 | J6: ПС «Каракамиш» 35/6 кВ
B7: Трёхфазый счётчик ЕХ518 124200573458 | E7: 1200/7 | F7: 0.4 | G7: 300 | H7: 12.2024 | I7: 12.2024 | J7: ПС «Каракамиш» 35/6 кВ

Sheet Структура пр 2
A1: 2022 год
A2: Структура параметров энергетического баланса | P2: Структура параметров энергетического баланса | AE2: Структура параметров энергетического баланса | AT2: Структура параметров энергетического баланса
M3: Таблица 2 | AB3: Таблица 2 | AQ3: Таблица 2 | BF3: Таблица 2
A4: 2022 год 1 квартал | P4: 2022 год 2 квартал | AE4: 2022 год 3 квартал | AT4: 2022 год 4 квартал
A5: Структура параметров баланса | B5: Электроэнергия | D5: Тепловая энергия | E5: Газ | F5: Мазут | G5: Уголь | H5: Нефтепродукты | M5: Вода | N5: Примечание | P5: Структура параметров баланса | Q5: Электроэнергия | S5: Тепловая энергия | T5: Газ | U5: Мазут | V5: Уголь | W5: Нефтепродукты | AB5: Вода | AC5: Примечание | AE5: Структура параметров баланса | AF5: Электроэнергия | AH5: Тепловая энергия | AI5: Газ | AJ5: Мазут | AK5: Уголь | AL5: Нефтепродукты | AQ5: Вода | AR5: Примечание | AT5: Структура параметров баланса | AU5: Электроэнергия | AW5: Тепловая энергия | AX5: Газ | AY5: Мазут | AZ5: Уголь | BA5: Нефтепродукты | BF5: Вода | BG5: Примечание
B6: актив Р | C6: реактив Q | H6: Д/Т | I6: Бензин | J6: Керосин | K6: Горюче-смазочные материалы | L6: Прочие | Q6: актив Р | R6: реактив Q | W6: Д/Т | X6: Бензин | Y6: Керосин | Z6: Горюче-смазочные материалы | AA6: Прочие | AF6: актив Р | AG6: реактив Q | AL6: Д/Т | AM6: Бензин | AN6: Керосин | AO6: Горюче-смазочные материалы | AP6: Прочие | AU6: актив Р | AV6: реактив Q | BA6: Д/Т | BB6: Бензин | BC6: Керосин | BD6: Горюче-смазочные материалы | BE6: Прочие
B7: кВт·ч | C7: кВар·ч | D7: Гкал | E7: тыс. м³ | F7: тонна | G7: тонна | H7: тонна | M7: м³ | Q7: кВт·ч | R7: кВар·ч | S7: Гкал | T7: тыс. м³ | U7: тонна | V7: тонна | W7: тонна | AB7: м³ | AF7: кВт·ч | AG7: кВар·ч | AH7: Гкал | AI7: тыс. м³ | AJ7: тонна | AK7: тонна | AL7: тонна | AQ7: м³ | AU7: кВт·ч | AV7: кВар·ч | AW7: Гкал | AX7: тыс. м³ | AY7: тонна | AZ7: тонна | BA7: тонна | BF7: м³
A8: Установленная электрическая мощность | B8: 1200000 | C8: 441600 | P8: Установленная электрическая мощность | Q8: 1200000 | R8: 441600 | AE8: Установленная электрическая мощность | AF8: 1200000 | AG8: 441600 | AT8: Установленная электрическая мощность | AU8: 1350000 | AV8: 500200
A9: транзитным абониментам | P9: транзитным абониментам | AE9: транзитным абониментам | AT9: транзитным абониментам
A10: Общее потребление по предприятию | B10: 1012524 | E10: 15.667 | K10: 1575 | M10: 2400 | P10: Общее потребление по предприятию | Q10: 917947 | T10: 3.736 | Z10: 1575 | AB10: 2400 | AE10: Общее потребление по предприятию | AF10: 1112517 | AI10: 2.487 | AO10: 1575 | AQ10: 2675 | AT10: Общее потребление по предприятию | AU10: 1046423 | AX10: 9.021 | BD10: 1575 | BF10: 2400
A11: для технологических нужд | B11: 795615 | P11: для технологических нужд | Q11: 721299 | AE11: для технологических нужд | AF11: 874187 | AT11: для технологических нужд | AU11: 822252
A12: для собственных нужд | B12: 20250 | E12: 1.296 | K12: 1575 | M12: 2400 | P12: для собственных нужд | Q12: 18359 | T12: 1.296 | Z12: 1575 | AB12: 2400 | AE12: для собственных нужд | AF12: 22250 | AI12: 1.296 | AO12: 1575 | AQ12: 2675 | AT12: для собственных нужд | AU12: 20928 | AX12: 1.296 | BD12: 1575 | BF12: 1575
A13: для производственных нужд | B13: 186358 | P13: для производственных нужд | Q13: 168950 | AE13: для производственных нужд | AF13: 204762 | AT13: для производственных нужд | AU13: 192597
A14: для хозяйственно-бытовых нужд | B14: 10301 | E14: 14.371 | P14: для хозяйственно-бытовых нужд | Q14: 9339 | T14: 2.44 | AE14: для хозяйственно-бытовых нужд | AF14: 11318 | AI14: 1.191 | AT14: для хозяйственно-бытовых нужд | AU14: 10646 | AX14: 7.725
A15: В разрезе видов выпускаемой продукции (основной и побочной) | B15: =B11+B13 -> 981973 | E15: =E11+E13 -> 0 | K15: =K11+K13 -> 0 | M15: =M11+M13 -> 0 | P15: В разрезе видов выпускаемой продукции (основной и побочной) | Q15: =Q11+Q13 -> 890249 | T15: =T11+T13 -> 0 | Z15: =Z11+Z13 -> 0 | AB15: =AB11+AB13 -> 0 | AE15: В разрезе видов выпускаемой продукции (основной и побочной) | AF15: =AF11+AF13 -> 1078949 | AI15: =AI11+AI13 -> 0 | AO15: =AO11+AO13 -> 0 | AQ15: =AQ11+AQ13 -> 0 | AT15: В разрезе видов выпускаемой продукции (основной и побочной) | AU15: =AU11+AU13 -> 1014849 | AX15: =AX11+AX13 -> 0 | BD15: =BD11+BD13 -> 0 | BF15: =BF11+BF13 -> 0
A16: 1. Продукция (услуга) | P16: 1. Продукция (услуга) | AE16: 1. Продукция (услуга) | AT16: 1. Продукция (услуга)
A17: труба ХВС | B17: 456574 | P17: труба ХВС | Q17: 470864 | AE17: труба ХВС | AF17: 278481 | AT17: труба ХВС | AU17: 340620
A18: фитинги ХВС и ГВС | B18: 291633 | P18: фитинги ХВС и ГВС | Q18: 121145 | AE18: фитинги ХВС и ГВС | AF18: 53092 | AT18: фитинги ХВС и ГВС | AU18: 41910
A19: канализационные трубы | B19: 8739 | P19: канализационные трубы | Q19: 191047 | AE19: канализационные трубы | AF19: 281331 | AT19: канализационные трубы | AU19: 505878
A20: канализационные фитинги | B20: 50336 | P20: канализационные фитинги | Q20: 168385 | AE20: канализационные фитинги | AF20: 132349 | AT20: канализационные фитинги | AU20: 121206
A21: тёплый пол | B21: 104556 | P21: тёплый пол | Q21: 96222 | AE21: тёплый пол | AF21: 90982 | AT21: тёплый пол | AU21: 118319
A23: 2023 год
A24: Структура параметров энергетического баланса | P24: Структура параметров энергетического баланса | AE24: Структура параметров энергетического баланса | AT24: Структура параметров энергетического баланса
M25: Таблица 2 | AB25: Таблица 2 | AQ25: Таблица 2 | BF25: Таблица 2
A26: 2023 год 1 квартал | P26: 2023 год 2 квартал | AE26: 2023 год 3 квартал | AT26: 2023 год 4 квартал
A27: Структура параметров баланса | B27: Электроэнергия | D27: Тепловая энергия | E27: Газ | F27: Мазут | G27: Уголь | H27: Нефтепродукты | M27: Вода | N27: Примечание | P27: Структура параметров баланса | Q27: Электроэнергия | S27: Тепловая энергия | T27: Газ | U27: Мазут | V27: Уголь | W27: Нефтепродукты | AB27: Вода | AC27: Примечание | AE27: Структура параметров баланса | AF27: Электроэнергия | AH27: Тепловая энергия | AI27: Газ | AJ27: Мазут | AK27: Уголь | AL27: Нефтепродукты | AQ27: Вода | AR27: Примечание | AT27: Структура параметров баланса | AU27: Электроэнергия | AW27: Тепловая энергия | AX27: Газ | AY27: Мазут | AZ27: Уголь | BA27: Нефтепродукты | BF27: Вода | BG27: Примечание
B28: актив Р | C28: реактив Q | H28: Д/Т | I28: Бензин | J28: Керосин | K28: Горюче-смазочные материалы | L28: Прочие | Q28: актив Р | R28: реактив Q | W28: Д/Т | X28: Бензин | Y28: Керосин | Z28: Горюче-смазочные материалы | AA28: Прочие | AF28: актив Р | AG28: реактив Q | AL28: Д/Т | AM28: Бензин | AN28: Керосин | AO28: Горюче-смазочные материалы | AP28: Прочие | AU28: актив Р | AV28: реактив Q | BA28: Д/Т | BB28: Бензин | BC28: Керосин | BD28: Горюче-смазочные материалы | BE28: Прочие
B29: кВт·ч | C29: кВар·ч | D29: Гкал | E29: тыс. м³ | F29: тонна | G29: тонна | H29: тонна | M29: м³ | Q29: кВт·ч | R29: кВар·ч | S29: Гкал | T29: тыс. м³ | U29: тонна | V29: тонна | W29: тонна | AB29: м³ | AF29: кВт·ч | AG29: кВар·ч | AH29: Гкал | AI29: тыс. м³ | AJ29: тонна | AK29: тонна | AL29: тонна | AQ29: м³ | AU29: кВт·ч | AV29: кВар·ч | AW29: Гкал | AX29: тыс. м³ | AY29: тонна | AZ29: тонна | BA29: тонна | BF29: м³
A30: Установленная электрическая мощность | B30: 1200000 | C30: 441600 | P30: Установленная электрическая мощность | Q30: 1200000 | R30: 441600 | AE30: Установленная электрическая мощность | AF30: 1200000 | AG30: 441600 | AT30: Установленная электрическая мощность | AU30: 1350000 | AV30: 500200
A31: транзитным абониментам | P31: транзитным абониментам | AE31: транзитным абониментам | AT31: транзитным абониментам
A32: Общее потребление по предприятию | B32: 973143 | E32: 14.0819 | K32: 652.5 | M32: 2400 | P32: Общее потребление по предприятию | Q32: 1322714 | T32: 3.382 | Z32: 652.5 | AB32: 2585 | AE32: Общее потребление по предприятию | AF32: 1488930 | AI32: 2.862 | AO32: 652.5 | AQ32: 2504 | AT32: Общее потребление по предприятию | AU32: 1488271 | AX32: 11.187 | BD32: 652.5 | BF32: 2150
A33: для технологических нужд | B33: 764671 | P33: для технологических нужд | Q33: 1039355 | AE33: для технологических нужд | AF33: 1169963 | AT33: для технологических нужд | AU33: 1169445
A34: для собственных нужд | B34: 19463 | E34: 1.296 | K34: 652.5 | M34: 2400 | P34: для собственных нужд | Q34: 26454 | T34: 1.296 | Z34: 652.5 | AB34: 2585 | AE34: для собственных нужд | AF34: 29779 | AI34: 1.296 | AO34: 652.5 | AQ34: 2504 | AT34: для собственных нужд | AU34: 29765 | AX34: 1.296 | BD34: 652.5 | BF34: 2150
A35: для производственных нужд | B35: 179109 | P35: для производственных нужд | Q35: 243449 | AE35: для производственных нужд | AF35: 274041 | AT35: для производственных нужд | AU35: 273920
A36: для хозяйственно-бытовых нужд | B36: 9900 | E36: 13.523 | P36: для хозяйственно-бытовых нужд | Q36: 13456 | T36: 2.086 | AE36: для хозяйственно-бытовых нужд | AF36: 15147 | AI36: 1.566 | AT36: для хозяйственно-бытовых нужд | AU36: 15141 | AX36: 9.891
A37: В разрезе видов выпускаемой продукции (основной и побочной) | B37: =B33+B35 -> 943780 | E37: =E33+E35 -> 0 | K37: =K33+K35 -> 0 | M37: =M33+M35 -> 0 | P37: В разрезе видов выпускаемой продукции (основной и побочной) | Q37: =Q33+Q35 -> 1282804 | T37: =T33+T35 -> 0 | Z37: =Z33+Z35 -> 0 | AB37: =AB33+AB35 -> 0 | AE37: В разрезе видов выпускаемой продукции (основной и побочной) | AF37: =AF33+AF35 -> 1444004 | AI37: =AI33+AI35 -> 0 | AO37: =AO33+AO35 -> 0 | AQ37: =AQ33+AQ35 -> 0 | AT37: В разрезе видов выпускаемой продукции (основной и побочной) | AU37: =AU33+AU35 -> 1443365 | AX37: =AX33+AX35 -> 0 | BD37: =BD33+BD35 -> 0 | BF37: =BF33+BF35 -> 0
A38: 1. Продукция (услуга) | P38: 1. Продукция (услуга) | AE38: 1. Продукция (услуга) | AT38: 1. Продукция (услуга)
A39: труба ХВС | B39: 597941 | P39: труба ХВС | Q39: 589193 | AE39: труба ХВС | AF39: 672778 | AT39: труба ХВС | AU39: 711350
A40: фитинги ХВС и ГВС | B40: 270720 | P40: фитинги ХВС и ГВС | Q40: 111057 | AE40: фитинги ХВС и ГВС | AF40: 200183 | AT40: фитинги ХВС и ГВС | AU40: 78717
A41: канализационные трубы | B41: 125199 | P41: канализационные трубы | Q41: 253058 | AE41: канализационные трубы | AF41: 294570 | AT41: канализационные трубы | AU41: 213958
...

Sheet Баланс
A1: Энергетический баланс предприятия
O2: Таблица 3
A3: Структура параметров баланса | C3: Электр энергияси | E3: Тепловая энергия | F3: Газ | G3: Мазут | H3: Уголь | J3: Нефтепродукты | O3: Вода | P3: Примечание | R3: не удалят | AQ3: 2022 год не трогат
C4: актив Р | D4: реактив Q | J4: Бензин | K4: Дизель | L4: Керосин | M4: ГСМ (Горюче-смазочные материалы) | N4: Прочее | R4: электр | W4: газ | AB4: ГСМ | AL4: Вода | AQ4: электр в т.у.т | AV4: газ в т.у.т | BA4: итого в т.у.т
AB5: Д/т | AC5: бензин | AD5: Д/т | AE5: бензин | AF5: Д/т | AG5: бензин | AH5: Д/т | AI5: бензин | AJ5: Д/т | AK5: бензин
E6: Гкал | F6: тыс. м | G6: тонна | H6: тонна | J6: тонна | O6: м³ | R6: 1 | S6: 2 | T6: 3 | U6: 4 | V6: год | W6: 1 | X6: 2 | Y6: 3 | Z6: 4 | AA6: год | AB6: 1 | AD6: 2 | AF6: 3 | AH6: 4 | AJ6: год | AL6: 1 | AM6: 2 | AN6: 3 | AO6: 4 | AP6: год | AQ6: 1 | AR6: 2 | AS6: 3 | AT6: 4 | AU6: год | AV6: 1 | AW6: 2 | AX6: 3 | AY6: 4 | AZ6: год | BA6: 1 | BB6: 2 | BC6: 3 | BD6: 4 | BE6: год
A7: Установленная электрическая мощность | C7: =V7 -> 4950000 | D7: ='Узел учета '!D5 -> 1825000 | R7: ='Структура пр 2'!B8 -> 1200000 | S7: ='Структура пр 2'!Q8 -> 1200000 | T7: ='Структура пр 2'!AF8 -> 1200000 | U7: ='Структура пр 2'!AU8 -> 1350000 | V7: =U7+T7+S7+R7 -> 4950000 | W7: ='Структура пр 2'!E8 -> 0 | X7: ='Структура пр 2'!T8 -> 0 | Y7: ='Структура пр 2'!AI8 -> 0 | Z7: ='Структура пр 2'!AX8 -> 0 | AA7: =Z7+Y7+X7+W7 -> 0 | AB7: ='Структура пр 2'!H8 -> 0 | AC7: ='Структура пр 2'!I8 -> 0 | AD7: ='Структура пр 2'!W8 -> 0 | AE7: ='Структура пр 2'!X8 -> 0 | AF7: ='Структура пр 2'!AL8 -> 0 | AG7: ='Структура пр 2'!AM8 -> 0 | AH7: ='Структура пр 2'!BA8 -> 0 | AI7: ='Структура пр 2'!BB8 -> 0 | AJ7: =AH7+AF7+AD7+AB7 -> 0 | AK7: ='Структура пр 2'!BB8 -> 0 | AL7: ='Структура пр 2'!M8 -> 0 | AM7: ='Структура пр 2'!AB8 -> 0 | AN7: ='Структура пр 2'!AQ8 -> 0 | AO7: ='Структура пр 2'!BF8 -> 0 | AP7: =AO7+AN7+AM7+AL7 -> 0 | AQ7: =R7/1000*0.123 -> 147.6 | AR7: =S7/1000*0.123 -> 147.6 | AS7: =T7/1000*0.123 -> 147.6 | AT7: =U7/1000*0.123 -> 166.05 | AU7: =V7/1000*0.123 -> 608.85 | AV7: =W7*1.16 -> 0 | AW7: =X7*1.16 -> 0 | AX7: =Y7*1.16 -> 0 | AY7: =Z7*1.16 -> 0 | AZ7: =AA7*1.16 -> 0 | BA7: =AQ7+AV7 -> 147.6 | BB7: =AR7+AW7 -> 147.6 | BC7: =AS7+AX7 -> 147.6 | BD7: =AT7+AY7 -> 166.05 | BE7: =AU7+AZ7 -> 608.85 | BF7: Установленная электрическая мощность
A8: Транзитным абониментам | R8: ='Структура пр 2'!B9 -> 0 | S8: ='Структура пр 2'!Q9 -> 0 | T8: ='Структура пр 2'!AF9 -> 0 | U8: ='Структура пр 2'!AU9 -> 0 | V8: =U8+T8+S8+R8 -> 0 | W8: ='Структура пр 2'!E9 -> 0 | X8: ='Структура пр 2'!T9 -> 0 | Y8: ='Структура пр 2'!AI9 -> 0 | Z8: ='Структура пр 2'!AX9 -> 0 | AA8: =Z8+Y8+X8+W8 -> 0 | AB8: ='Структура пр 2'!H9 -> 0 | AC8: ='Структура пр 2'!I9 -> 0 | AD8: ='Структура пр 2'!W9 -> 0 | AE8: ='Структура пр 2'!X9 -> 0 | AF8: ='Структура пр 2'!AL9 -> 0 | AG8: ='Структура пр 2'!AM9 -> 0 | AH8: ='Структура пр 2'!BA9 -> 0 | AI8: ='Структура пр 2'!BB9 -> 0 | AJ8: =AH8+AF8+AD8+AB8 -> 0 | AK8: ='Структура пр 2'!BB9 -> 0 | AL8: ='Структура пр 2'!M9 -> 0 | AM8: ='Структура пр 2'!AB9 -> 0 | AN8: ='Структура пр 2'!AQ9 -> 0 | AO8: ='Структура пр 2'!BF9 -> 0 | AP8: =AO8+AN8+AM8+AL8 -> 0 | AQ8: =R8/1000*0.123 -> 0 | AR8: =S8/1000*0.123 -> 0 | AS8: =T8/1000*0.123 -> 0 | AT8: =U8/1000*0.123 -> 0 | AU8: =V8/1000*0.123 -> 0 | AV8: =W8*1.16 -> 0 | AW8: =X8*1.16 -> 0 | AX8: =Y8*1.16 -> 0 | AY8: =Z8*1.16 -> 0 | AZ8: =AA8*1.16 -> 0 | BA8: =AQ8+AV8 -> 0 | BB8: =AR8+AW8 -> 0 | BC8: =AS8+AX8 -> 0 | BD8: =AT8+AY8 -> 0 | BE8: =AU8+AZ8 -> 0 | BF8: Транзитным абониментам
A9: Общее потребление по предприятию | C9: =V9 -> 4089411 | F9: =AA9 -> 30.911 | R9: ='Структура пр 2'!B10 -> 1012524 | S9: ='Структура пр 2'!Q10 -> 917947 | T9: ='Структура пр 2'!AF10 -> 1112517 | U9: ='Структура пр 2'!AU10 -> 1046423 | V9: =U9+T9+S9+R9 -> 4089411 | W9: ='Структура пр 2'!E10 -> 15.667 | X9: ='Структура пр 2'!T10 -> 3.736 | Y9: ='Структура пр 2'!AI10 -> 2.487 | Z9: ='Структура пр 2'!AX10 -> 9.021 | AA9: =Z9+Y9+X9+W9 -> 30.911 | AB9: ='Структура пр 2'!H10 -> 0 | AC9: ='Структура пр 2'!I10 -> 0 | AD9: ='Структура пр 2'!W10 -> 0 | AE9: ='Структура пр 2'!X10 -> 0 | AF9: ='Структура пр 2'!AL10 -> 0 | AG9: ='Структура пр 2'!AM10 -> 0 | AH9: ='Структура пр 2'!BA10 -> 0 | AI9: ='Структура пр 2'!BB10 -> 0 | AJ9: =AH9+AF9+AD9+AB9 -> 0 | AK9: ='Структура пр 2'!BB10 -> 0 | AL9: ='Структура пр 2'!M10 -> 2400 | AM9: ='Структура пр 2'!AB10 -> 2400 | AN9: ='Структура пр 2'!AQ10 -> 2675 | AO9: ='Структура пр 2'!BF10 -> 2400 | AP9: =AO9+AN9+AM9+AL9 -> 9875 | AQ9: =R9/1000*0.123 -> 124.54045 | AR9: =S9/1000*0.123 -> 112.90748 | AS9: =T9/1000*0.123 -> 136.83959 | AT9: =U9/1000*0.123 -> 128.71003 | AU9: =V9/1000*0.123 -> 502.99755 | AV9: =W9*1.16 -> 18.17372 | AW9: =X9*1.16 -> 4.33376 | AX9: =Y9*1.16 -> 2.88492 | AY9: =Z9*1.16 -> 10.46436 | AZ9: =AA9*1.16 -> 35.85676 | BA9: =AQ9+AV9 -> 142.71417 | BB9: =AR9+AW9 -> 117.24124 | BC9: =AS9+AX9 -> 139.72451 | BD9: =AT9+AY9 -> 139.17439 | BE9: =AU9+AZ9 -> 538.85431 | BF9: Общее потребление по предприятию
A10: – на технологические нужды | C10: =V10 -> 3213353 | R10: ='Структура пр 2'!B11 -> 795615 | S10: ='Структура пр 2'!Q11 -> 721299 | T10: ='Структура пр 2'!AF11 -> 874187 | U10: ='Структура пр 2'!AU11 -> 822252 | V10: =U10+T10+S10+R10 -> 3213353 | W10: ='Структура пр 2'!E11 -> 0 | X10: ='Структура пр 2'!T11 -> 0 | Y10: ='Структура пр 2'!AI11 -> 0 | Z10: ='Структура пр 2'!AX11 -> 0 | AA10: =Z10+Y10+X10+W10 -> 0 | AB10: ='Структура пр 2'!H11 -> 0 | AC10: ='Структура пр 2'!I11 -> 0 | AD10: ='Структура пр 2'!W11 -> 0 | AE10: ='Структура пр 2'!X11 -> 0 | AF10: ='Структура пр 2'!AL11 -> 0 | AG10: ='Структура пр 2'!AM11 -> 0 | AH10: ='Структура пр 2'!BA11 -> 0 | AI10: ='Структура пр 2'!BB11 -> 0 | AJ10: =AH10+AF10+AD10+AB10 -> 0 | AK10: ='Структура пр 2'!BB11 -> 0 | AL10: ='Структура пр 2'!M11 -> 0 | AM10: ='Структура пр 2'!AB11 -> 0 | AN10: ='Структура пр 2'!AQ11 -> 0 | AO10: ='Структура пр 2'!BF11 -> 0 | AP10: =AO10+AN10+AM10+AL10 -> 0 | AQ10: =R10/1000*0.123 -> 97.860645 | AR10: =S10/1000*0.123 -> 88.719777 | AS10: =T10/1000*0.123 -> 107.525 | AT10: =U10/1000*0.123 -> 101.137 | AU10: =V10/1000*0.123 -> 395.24242 | AV10: =W10*1.16 -> 0 | AW10: =X10*1.16 -> 0 | AX10: =Y10*1.16 -> 0 | AY10: =Z10*1.16 -> 0 | AZ10: =AA10*1.16 -> 0 | BA10: =AQ10+AV10 -> 97.860645 | BB10: =AR10+AW10 -> 88.719777 | BC10: =AS10+AX10 -> 107.525 | BD10: =AT10+AY10 -> 101.137 | BE10: =AU10+AZ10 -> 395.24242 | BF10: – на технологические нужды
A11: – на собственные нужды предприятия | C11: =V11 -> 81787 | F11: =AA11 -> 5.184 | R11: ='Структура пр 2'!B12 -> 20250 | S11: ='Структура пр 2'!Q12 -> 18359 | T11: ='Структура пр 2'!AF12 -> 22250 | U11: ='Структура пр 2'!AU12 -> 20928 | V11: =U11+T11+S11+R11 -> 81787 | W11: ='Структура пр 2'!E12 -> 1.296 | X11: ='Структура пр 2'!T12 -> 1.296 | Y11: ='Структура пр 2'!AI12 -> 1.296 | Z11: ='Структура пр 2'!AX12 -> 1.296 | AA11: =Z11+Y11+X11+W11 -> 5.184 | AB11: ='Структура пр 2'!H12 -> 0 | AC11: ='Структура пр 2'!I12 -> 0 | AD11: ='Структура пр 2'!W12 -> 0 | AE11: ='Структура пр 2'!X12 -> 0 | AF11: ='Структура пр 2'!AL12 -> 0 | AG11: ='Структура пр 2'!AM12 -> 0 | AH11: ='Структура пр 2'!BA12 -> 0 | AI11: ='Структура пр 2'!BB12 -> 0 | AJ11: =AH11+AF11+AD11+AB11 -> 0 | AK11: ='Структура пр 2'!BB12 -> 0 | AL11: ='Структура пр 2'!M12 -> 2400 | AM11: ='Структура пр 2'!AB12 -> 2400 | AN11: ='Структура пр 2'!AQ12 -> 2675 | AO11: ='Структура пр 2'!BF12 -> 1575 | AP11: =AO11+AN11+AM11+AL11 -> 9050 | AQ11: =R11/1000*0.123 -> 2.49075 | AR11: =S11/1000*0.123 -> 2.258157 | AS11: =T11/1000*0.123 -> 2.73675 | AT11: =U11/1000*0.123 -> 2.574144 | AU11: =V11/1000*0.123 -> 10.059801 | AV11: =W11*1.16 -> 1.50336 | AW11: =X11*1.16 -> 1.50336 | AX11: =Y11*1.16 -> 1.50336 | AY11: =Z11*1.16 -> 1.50336 | AZ11: =AA11*1.16 -> 6.01344 | BA11: =AQ11+AV11 -> 3.99411 | BB11: =AR11+AW11 -> 3.761517 | BC11: =AS11+AX11 -> 4.24011 | BD11: =AT11+AY11 -> 4.077504 | BE11: =AU11+AZ11 -> 16.073241 | BF11: – на собственные нужды предприятия
A12: – на производственные нужды | C12: =V12 -> 752667 | R12: ='Структура пр 2'!B13 -> 186358 | S12: ='Структура пр 2'!Q13 -> 168950 | T12: ='Структура пр 2'!AF13 -> 204762 | U12: ='Структура пр 2'!AU13 -> 192597 | V12: =U12+T12+S12+R12 -> 752667 | W12: ='Структура пр 2'!E13 -> 0 | X12: ='Структура пр 2'!T13 -> 0 | Y12: ='Структура пр 2'!AI13 -> 0 | Z12: ='Структура пр 2'!AX13 -> 0 | AA12: =Z12+Y12+X12+W12 -> 0 | AB12: ='Структура пр 2'!H13 -> 0 | AC12: ='Структура пр 2'!I13 -> 0 | AD12: ='Структура пр 2'!W13 -> 0 | AE12: ='Структура пр 2'!X13 -> 0 | AF12: ='Структура пр 2'!AL13 -> 0 | AG12: ='Структура пр 2'!AM13 -> 0 | AH12: ='Структура пр 2'!BA13 -> 0 | AI12: ='Структура пр 2'!BB13 -> 0 | AJ12: =AH12+AF12+AD12+AB12 -> 0 | AK12: ='Структура пр 2'!BB13 -> 0 | AL12: ='Структура пр 2'!M13 -> 0 | AM12: ='Структура пр 2'!AB13 -> 0 | AN12: ='Структура пр 2'!AQ13 -> 0 | AO12: ='Структура пр 2'!BF13 -> 0 | AP12: =AO12+AN12+AM12+AL12 -> 0 | AQ12: =R12/1000*0.123 -> 22.922034 | AR12: =S12/1000*0.123 -> 20.78085 | AS12: =T12/1000*0.123 -> 25.185726 | AT12: =U12/1000*0.123 -> 23.689431 | AU12: =V12/1000*0.123 -> 92.578041 | AV12: =W12*1.16 -> 0 | AW12: =X12*1.16 -> 0 | AX12: =Y12*1.16 -> 0 | AY12: =Z12*1.16 -> 0 | AZ12: =AA12*1.16 -> 0 | BA12: =AQ12+AV12 -> 22.922034 | BB12: =AR12+AW12 -> 20.78085 | BC12: =AS12+AX12 -> 25.185726 | BD12: =AT12+AY12 -> 23.689431 | BE12: =AU12+AZ12 -> 92.578041 | BF12: – на производственные нужды
A13: – на хозяйственно-бытовые нужды | C13: =V13 -> 41604 | F13: =AA13 -> 25.727 | R13: ='Структура пр 2'!B14 -> 10301 | S13: ='Структура пр 2'!Q14 -> 9339 | T13: ='Структура пр 2'!AF14 -> 11318 | U13: ='Структура пр 2'!AU14 -> 10646 | V13: =U13+T13+S13+R13 -> 41604 | W13: ='Структура пр 2'!E14 -> 14.371 | X13: ='Структура пр 2'!T14 -> 2.44 | Y13: ='Структура пр 2'!AI14 -> 1.191 | Z13: ='Структура пр 2'!AX14 -> 7.725 | AA13: =Z13+Y13+X13+W13 -> 25.727 | AB13: ='Структура пр 2'!H14 -> 0 | AC13: ='Структура пр 2'!I14 -> 0 | AD13: ='Структура пр 2'!AL14 -> 0 | AE13: ='Структура пр 2'!X14 -> 0 | AF13: ='Структура пр 2'!AL14 -> 0 | AG13: ='Структура пр 2'!AM14 -> 0 | AH13: ='Структура пр 2'!BA14 -> 0 | AI13: ='Структура пр 2'!BB14 -> 0 | AJ13: =AH13+AF13+AD13+AB13 -> 0 | AK13: ='Структура пр 2'!BB14 -> 0 | AL13: ='Структура пр 2'!M14 -> 0 | AM13: ='Структура пр 2'!AB14 -> 0 | AN13: ='Структура пр 2'!AQ14 -> 0 | AO13: ='Структура пр 2'!BF14 -> 0 | AP13: =AO13+AN13+AM13+AL13 -> 0 | AQ13: =R13/1000*0.123 -> 1.267023 | AR13: =S13/1000*0.123 -> 1.148697 | AS13: =T13/1000*0.123 -> 1.392114 | AT13: =U13/1000*0.123 -> 1.309458 | AU13: =V13/1000*0.123 -> 5.117292 | AV13: =W13*1.16 -> 16.67036 | AW13: =X13*1.16 -> 2.8304 | AX13: =Y13*1.16 -> 1.38156 | AY13: =Z13*1.16 -> 8.961 | AZ13: =AA13*1.16 -> 29.84332 | BA13: =AQ13+AV13 -> 17.937383 | BB13: =AR13+AW13 -> 3.979097 | BC13: =AS13+AX13 -> 2.773674 | BD13: =AT13+AY13 -> 10.270458 | BE13: =AU13+AZ13 -> 34.960612 | BF13: – на хозяйственно-бытовые нужды
A14: В разрезе видов выпускаемой продукции (основной и побочной) | C14: =V14 -> 3966020 | F14: =AA14 -> 0 | J14: =AK14 -> 0 | K14: =AJ14 -> 0 | O14: =AP14 -> 0 | R14: ='Структура пр 2'!B15 -> 981973 | S14: ='Структура пр 2'!Q15 -> 890249 | T14: ='Структура пр 2'!AF15 -> 1078949 | U14: ='Структура пр 2'!AU15 -> 1014849 | V14: =U14+T14+S14+R14 -> 3966020 | W14: ='Структура пр 2'!D15 -> 0 | X14: ='Структура пр 2'!T15 -> 0 | Y14: ='Структура пр 2'!AI15 -> 0 | Z14: ='Структура пр 2'!AW15 -> 0 | AA14: =Z14+Y14+X14+W14 -> 0 | AB14: ='Структура пр 2'!H15 -> 0 | AC14: ='Структура пр 2'!I15 -> 0 | AD14: ='Структура пр 2'!W15 -> 0 | AE14: ='Структура пр 2'!X15 -> 0 | AF14: ='Структура пр 2'!AL15 -> 0 | AG14: ='Структура пр 2'!AM15 -> 0 | AH14: ='Структура пр 2'!BA15 -> 0 | AI14: ='Структура пр 2'!BB15 -> 0 | AJ14: =AH14+AF14+AD14+AB14 -> 0 | AK14: ='Структура пр 2'!BB15 -> 0 | AL14: ='Структура пр 2'!M15 -> 0 | AM14: ='Структура пр 2'!AB15 -> 0 | AN14: ='Структура пр 2'!AQ15 -> 0 | AO14: ='Структура пр 2'!BF15 -> 0 | AP14: =AO14+AN14+AM14+AL14 -> 0 | AQ14: =R14/1000*0.123 -> 120.78268 | AR14: =S14/1000*0.123 -> 109.50063 | AS14: =T14/1000*0.123 -> 132.71073 | AT14: =U14/1000*0.123 -> 124.82643 | AU14: =V14/1000*0.123 -> 487.82046 | AV14: =W14*1.16 -> 0 | AW14: =X14*1.16 -> 0 | AX14: =Y14*1.16 -> 0 | AY14: =Z14*1.16 -> 0 | AZ14: =AA14*1.16 -> 0 | BA14: =AQ14+AV14 -> 120.78268 | BB14: =AR14+AW14 -> 109.50063 | BC14: =AS14+AX14 -> 132.71073 | BD14: =AT14+AY14 -> 124.82643 | BE14: =AU14+AZ14 -> 487.82046 | BF14: В разрезе видов выпускаемой продукции (основной и побочной)
A15: 1. Продукция (услуга): труба ХВС, фитинги ХВС и ГВС, канализационные трубы и фитинги, тёплый пол | C15: =V15 -> 3923669 | R15: ='Структура пр 2'!B17+'Структура пр 2'!B18+'Структура пр 2'!B19+'Структура пр 2'!B20+'Структура пр 2'!B21 -> 911838 | S15: ='Структура пр 2'!Q17+'Структура пр 2'!Q18+'Структура пр 2'!Q19+'Структура пр 2'!Q20+'Структура пр 2'!Q21 -> 1047663 | T15: ='Структура пр 2'!AF17+'Структура пр 2'!AF18+'Структура пр 2'!AF19+'Структура пр 2'!AF20+'Структура пр 2'!AF21 -> 836235 | U15: ='Структура пр 2'!AU17+'Структура пр 2'!AU18+'Структура пр 2'!AU19+'Структура пр 2'!AU20+'Структура пр 2'!AU21 -> 1127933 | V15: =U15+T15+S15+R15 -> 3923669 | AA15: =Z15+Y15+X15+W15 -> 0 | AJ15: =AH15+AF15+AD15+AB15 -> 0 | AK15: ='Структура пр 2'!BB16 -> 0 | AP15: =AO15+AN15+AM15+AL15 -> 0 | AU15: =V15/1000*0.123 -> 482.61129 | AZ15: =AA15*1.16 -> 0 | BE15: =AU15+AZ15 -> 482.61129
A19: Энергетический баланс предприятия
O20: Таблица 3
A21: Структура параметров баланса | C21: Электр энергияси | E21: Тепловая энергия | F21: Газ | G21: Мазут | H21: Уголь | J21: Нефтепродукты | O21: Вода | P21: Примечание | R21: не удалят | AQ21: 2023 год не трогат
C22: актив Р | D22: реактив Q | J22: Бензин | K22: Дизель | L22: Керосин | M22: ГСМ (Горюче-смазочные материалы) | N22: Прочее | R22: электр | W22: газ | AB22: ГСМ | AL22: Вода | AQ22: электр в т.у.т | AV22: газ в т.у.т | BA22: итого в т.у.т
AB23: Д/т | AC23: бензин | AD23: Д/т | AE23: бензин | AF23: Д/т | AG23: бензин | AH23: Д/т | AI23: бензин | AJ23: Д/т | AK23: бензин
E24: Гкал | F24: тыс. м | G24: тонна | H24: тонна | J24: тонна | O24: м³ | R24: 1 | S24: 2 | T24: 3 | U24: 4 | V24: год | W24: 1 | X24: 2 | Y24: 3 | Z24: 4 | AA24: год | AB24: 1 | AD24: 2 | AF24: 3 | AH24: 4 | AJ24: год | AL24: 1 | AM24: 2 | AN24: 3 | AO24: 4 | AP24: год | AQ24: 1 | AR24: 2 | AS24: 3 | AT24: 4 | AU24: год | AV24: 1 | AW24: 2 | AX24: 3 | AY24: 4 | AZ24: год | BA24: 1 | BB24: 2 | BC24: 3 | BD24: 4 | BE24: год
A25: Установленная электрическая мощность | C25: =V25 -> 4950000 | D25: ='Узел учета '!D5 -> 1825000 | R25: ='Структура пр 2'!B30 -> 1200000 | S25: ='Структура пр 2'!Q30 -> 1200000 | T25: ='Структура пр 2'!AF30 -> 1200000 | U25: ='Структура пр 2'!AU30 -> 1350000 | V25: =U25+T25+S25+R25 -> 4950000 | W25: ='Структура пр 2'!E30 -> 0 | X25: ='Структура пр 2'!T30 -> 0 | Y25: ='Структура пр 2'!AI30 -> 0 | Z25: ='Структура пр 2'!AX30 -> 0 | AA25: =Z25+Y25+X25+W25 -> 0 | AB25: ='Структура пр 2'!H30 -> 0 | AC25: ='Структура пр 2'!I30 -> 0 | AD25: ='Структура пр 2'!W30 -> 0 | AE25: ='Структура пр 2'!X30 -> 0 | AF25: ='Структура пр 2'!AL30 -> 0 | AG25: ='Структура пр 2'!AM30 -> 0 | AH25: ='Структура пр 2'!BA30 -> 0 | AI25: ='Структура пр 2'!BB30 -> 0 | AJ25: =AH25+AF25+AD25+AB25 -> 0 | AK25: ='Структура пр 2'!BB32 -> 0 | AL25: ='Структура пр 2'!M30 -> 0 | AM25: ='Структура пр 2'!AB30 -> 0 | AN25: ='Структура пр 2'!AQ30 -> 0 | AO25: ='Структура пр 2'!BF30 -> 0 | AP25: =AO25+AN25+AM25+AL25 -> 0 | AQ25: =R25/1000*0.123 -> 147.6 | AR25: =S25/1000*0.123 -> 147.6 | AS25: =T25/1000*0.123 -> 147.6 | AT25: =U25/1000*0.123 -> 166.05 | AU25: =V25/1000*0.123 -> 608.85 | AV25: =W25*1.16 -> 0 | AW25: =X25*1.16 -> 0 | AX25: =Y25*1.16 -> 0 | AY25: =Z25*1.16 -> 0 | AZ25: =AA25*1.16 -> 0 | BA25: =AQ25+AV25 -> 147.6 | BB25: =AR25+AW25 -> 147.6 | BC25: =AS25+AX25 -> 147.6 | BD25: =AT25+AY25 -> 166.05 | BE25: =AU25+AZ25 -> 608.85 | BF25: Установленная электрическая мощность
A26: Транзитным абониментам | R26: ='Структура пр 2'!B31 -> 0 | S26: ='Структура пр 2'!Q31 -> 0 | T26: ='Структура пр 2'!AF31 -> 0 | U26: ='Структура пр 2'!AU31 -> 0 | V26: =U26+T26+S26+R26 -> 0 | W26: ='Структура пр 2'!E31 -> 0 | X26: ='Структура пр 2'!T31 -> 0 | Y26: ='Структура пр 2'!AI31 -> 0 | Z26: ='Структура пр 2'!AX31 -> 0 | AA26: =Z26+Y26+X26+W26 -> 0 | AB26: ='Структура пр 2'!H31 -> 0 | AC26: ='Структура пр 2'!I31 -> 0 | AD26: ='Структура пр 2'!W31 -> 0 | AE26: ='Структура пр 2'!X31 -> 0 | AF26: ='Структура пр 2'!AL31 -> 0 | AG26: ='Структура пр 2'!AM31 -> 0 | AH26: ='Структура пр 2'!BA31 -> 0 | AI26: ='Структура пр 2'!BB31 -> 0 | AJ26: =AH26+AF26+AD26+AB26 -> 0 | AK26: ='Структура пр 2'!BB33 -> 0 | AL26: ='Структура пр 2'!M31 -> 0 | AM26: ='Структура пр 2'!AB31 -> 0 | AN26: ='Структура пр 2'!AQ31 -> 0 | AO26: ='Структура пр 2'!BF31 -> 0 | AP26: =AO26+AN26+AM26+AL26 -> 0 | AQ26: =R26/1000*0.123 -> 0 | AR26: =S26/1000*0.123 -> 0 | AS26: =T26/1000*0.123 -> 0 | AT26: =U26/1000*0.123 -> 0 | AU26: =V26/1000*0.123 -> 0 | AV26: =W26*1.16 -> 0 | AW26: =X26*1.16 -> 0 | AX26: =Y26*1.16 -> 0 | AY26: =Z26*1.16 -> 0 | AZ26: =AA26*1.16 -> 0 | BA26: =AQ26+AV26 -> 0 | BB26: =AR26+AW26 -> 0 | BC26: =AS26+AX26 -> 0 | BD26: =AT26+AY26 -> 0 | BE26: =AU26+AZ26 -> 0 | BF26: Транзитным абониментам
A27: Общее потребление по предприятию | C27: =V27 -> 5273058 | F27: =AA27 -> 31.5129 | R27: ='Структура пр 2'!B32 -> 973143 | S27: ='Структура пр 2'!Q32 -> 1322714 | T27: ='Структура пр 2'!AF32 -> 1488930 | U27: ='Структура пр 2'!AU32 -> 1488271 | V27: =U27+T27+S27+R27 -> 5273058 | W27: ='Структура пр 2'!E32 -> 14.0819 | X27: ='Структура пр 2'!T32 -> 3.382 | Y27: ='Структура пр 2'!AI32 -> 2.862 | Z27: ='Структура пр 2'!AX32 -> 11.187 | AA27: =Z27+Y27+X27+W27 -> 31.5129 | AB27: ='Структура пр 2'!H32 -> 0 | AC27: ='Структура пр 2'!I32 -> 0 | AD27: ='Структура пр 2'!W32 -> 0 | AE27: ='Структура пр 2'!X32 -> 0 | AF27: ='Структура пр 2'!AL32 -> 0 | AG27: ='Структура пр 2'!AM32 -> 0 | AH27: ='Структура пр 2'!BA32 -> 0 | AI27: ='Структура пр 2'!BB32 -> 0 | AJ27: =AH27+AF27+AD27+AB27 -> 0 | AK27: ='Структура пр 2'!BB34 -> 0 | AL27: ='Структура пр 2'!M32 -> 2400 | AM27: ='Структура пр 2'!AB32 -> 2585 | AN27: ='Структура пр 2'!AQ32 -> 2504 | AO27: ='Структура пр 2'!BF32 -> 2150 | AP27: =AO27+AN27+AM27+AL27 -> 9639 | AQ27: =R27/1000*0.123 -> 119.69659 | AR27: =S27/1000*0.123 -> 162.69382 | AS27: =T27/1000*0.123 -> 183.13839 | AT27: =U27/1000*0.123 -> 183.05733 | AU27: =V27/1000*0.123 -> 648.58613 | AV27: =W27*1.16 -> 16.335004 | AW27: =X27*1.16 -> 3.92312 | AX27: =Y27*1.16 -> 3.31992 | AY27: =Z27*1.16 -> 12.97692 | AZ27: =AA27*1.16 -> 36.554964 | BA27: =AQ27+AV27 -> 136.03159 | BB27: =AR27+AW27 -> 166.61694 | BC27: =AS27+AX27 -> 186.45831 | BD27: =AT27+AY27 -> 196.03425 | BE27: =AU27+AZ27 -> 685.1411 | BF27: Общее потребление по предприятию
A28: – на технологические нужды | C28: =V28 -> 4143434 | R28: ='Структура пр 2'!B33 -> 764671 | S28: ='Структура пр 2'!Q33 -> 1039355 | T28: ='Структура пр 2'!AF33 -> 1169963 | U28: ='Структура пр 2'!AU33 -> 1169445 | V28: =U28+T28+S28+R28 -> 4143434 | W28: ='Структура пр 2'!E33 -> 0 | X28: ='Структура пр 2'!T33 -> 0 | Y28: ='Структура пр 2'!AI33 -> 0 | Z28: ='Структура пр 2'!AX33 -> 0 | AA28: =Z28+Y28+X28+W28 -> 0 | AB28: ='Структура пр 2'!H33 -> 0 | AC28: ='Структура пр 2'!I33 -> 0 | AD28: ='Структура пр 2'!W33 -> 0 | AE28: ='Структура пр 2'!X33 -> 0 | AF28: ='Структура пр 2'!AL33 -> 0 | AG28: ='Структура пр 2'!AM33 -> 0 | AH28: ='Структура пр 2'!BA33 -> 0 | AI28: ='Структура пр 2'!BB33 -> 0 | AJ28: =AH28+AF28+AD28+AB28 -> 0 | AK28: ='Структура пр 2'!BB35 -> 0 | AL28: ='Структура пр 2'!M33 -> 0 | AM28: ='Структура пр 2'!AB33 -> 0 | AN28: ='Структура пр 2'!AQ33 -> 0 | AO28: ='Структура пр 2'!BF33 -> 0 | AP28: =AO28+AN28+AM28+AL28 -> 0 | AQ28: =R28/1000*0.123 -> 94.054533 | AR28: =S28/1000*0.123 -> 127.84067 | AS28: =T28/1000*0.123 -> 143.90545 | AT28: =U28/1000*0.123 -> 143.84173 | AU28: =V28/1000*0.123 -> 509.64238 | AV28: =W28*1.16 -> 0 | AW28: =X28*1.16 -> 0 | AX28: =Y28*1.16 -> 0 | AY28: =Z28*1.16 -> 0 | AZ28: =AA28*1.16 -> 0 | BA28: =AQ28+AV28 -> 94.054533 | BB28: =AR28+AW28 -> 127.84067 | BC28: =AS28+AX28 -> 143.90545 | BD28: =AT28+AY28 -> 143.84173 | BE28: =AU28+AZ28 -> 509.64238 | BF28: – на технологические нужды
A29: – на собственные нужды предприятия | C29: =V29 -> 105461 | F29: =AA29 -> 5.184 | R29: ='Структура пр 2'!B34 -> 19463 | S29: ='Структура пр 2'!Q34 -> 26454 | T29: ='Структура пр 2'!AF34 -> 29779 | U29: ='Структура пр 2'!AU34 -> 29765 | V29: =U29+T29+S29+R29 -> 105461 | W29: ='Структура пр 2'!E34 -> 1.296 | X29: ='Структура пр 2'!T34 -> 1.296 | Y29: ='Структура пр 2'!AI34 -> 1.296 | Z29: ='Структура пр 2'!AX34 -> 1.296 | AA29: =Z29+Y29+X29+W29 -> 5.184 | AB29: ='Структура пр 2'!H34 -> 0 | AC29: ='Структура пр 2'!I34 -> 0 | AD29: ='Структура пр 2'!W34 -> 0 | AE29: ='Структура пр 2'!X34 -> 0 | AF29: ='Структура пр 2'!AL34 -> 0 | AG29: ='Структура пр 2'!AM34 -> 0 | AH29: ='Структура пр 2'!BA34 -> 0 | AI29: ='Структура пр 2'!BB34 -> 0 | AJ29: =AH29+AF29+AD29+AB29 -> 0 | AK29: ='Структура пр 2'!BB36 -> 0 | AL29: ='Структура пр 2'!M34 -> 2400 | AM29: ='Структура пр 2'!AB34 -> 2585 | AN29: ='Структура пр 2'!AQ34 -> 2504 | AO29: ='Структура пр 2'!BF34 -> 2150 | AP29: =AO29+AN29+AM29+AL29 -> 9639 | AQ29: =R29/1000*0.123 -> 2.393949 | AR29: =S29/1000*0.123 -> 3.253842 | AS29: =T29/1000*0.123 -> 3.662817 | AT29: =U29/1000*0.123 -> 3.661095 | AU29: =V29/1000*0.123 -> 12.971703 | AV29: =W29*1.16 -> 1.50336 | AW29: =X29*1.16 -> 1.50336 | AX29: =Y29*1.16 -> 1.50336 | AY29: =Z29*1.16 -> 1.50336 | AZ29: =AA29*1.16 -> 6.01344 | BA29: =AQ29+AV29 -> 3.897309 | BB29: =AR29+AW29 -> 4.757202 | BC29: =AS29+AX29 -> 5.166177 | BD29: =AT29+AY29 -> 5.164455 | BE29: =AU29+AZ29 -> 18.985143 | BF29: – на собственные нужды предприятия
A30: – на производственные нужды | C30: =V30 -> 970519 | R30: ='Структура пр 2'!B35 -> 179109 | S30: ='Структура пр 2'!Q35 -> 243449 | T30: ='Структура пр 2'!AF35 -> 274041 | U30: ='Структура пр 2'!AU35 -> 273920 | V30: =U30+T30+S30+R30 -> 970519 | W30: ='Структура пр 2'!E35 -> 0 | X30: ='Структура пр 2'!T35 -> 0 | Y30: ='Структура пр 2'!AI35 -> 0 | Z30: ='Структура пр 2'!AX35 -> 0 | AA30: =Z30+Y30+X30+W30 -> 0 | AB30: ='Структура пр 2'!H35 -> 0 | AC30: ='Структура пр 2'!I35 -> 0 | AD30: ='Структура пр 2'!W35 -> 0 | AE30: ='Структура пр 2'!X35 -> 0 | AF30: ='Структура пр 2'!AL35 -> 0 | AG30: ='Структура пр 2'!AM35 -> 0 | AH30: ='Структура пр 2'!BA35 -> 0 | AI30: ='Структура пр 2'!BB35 -> 0 | AJ30: =AH30+AF30+AD30+AB30 -> 0 | AK30: ='Структура пр 2'!BB37 -> 0 | AL30: ='Структура пр 2'!M35 -> 0 | AM30: ='Структура пр 2'!AB35 -> 0 | AN30: ='Структура пр 2'!AQ35 -> 0 | AO30: ='Структура пр 2'!BF35 -> 0 | AP30: =AO30+AN30+AM30+AL30 -> 0 | AQ30: =R30/1000*0.123 -> 22.030407 | AR30: =S30/1000*0.123 -> 29.944227 | AS30: =T30/1000*0.123 -> 33.707043 | AT30: =U30/1000*0.123 -> 33.69216 | AU30: =V30/1000*0.123 -> 119.37384 | AV30: =W30*1.16 -> 0 | AW30: =X30*1.16 -> 0 | AX30: =Y30*1.16 -> 0 | AY30: =Z30*1.16 -> 0 | AZ30: =AA30*1.16 -> 0 | BA30: =AQ30+AV30 -> 22.030407 | BB30: =AR30+AW30 -> 29.944227 | BC30: =AS30+AX30 -> 33.707043 | BD30: =AT30+AY30 -> 33.69216 | BE30: =AU30+AZ30 -> 119.37384 | BF30: – на производственные нужды
A31: – на хозяйственно-бытовые нужды | C31: =V31 -> 53644 | F31: =AA31 -> 27.066 | R31: ='Структура пр 2'!B36 -> 9900 | S31: ='Структура пр 2'!Q36 -> 13456 | T31: ='Структура пр 2'!AF36 -> 15147 | U31: ='Структура пр 2'!AU36 -> 15141 | V31: =U31+T31+S31+R31 -> 53644 | W31: ='Структура пр 2'!E36 -> 13.523 | X31: ='Структура пр 2'!T36 -> 2.086 | Y31: ='Структура пр 2'!AI36 -> 1.566 | Z31: ='Структура пр 2'!AX36 -> 9.891 | AA31: =Z31+Y31+X31+W31 -> 27.066 | AB31: ='Структура пр 2'!H36 -> 0 | AC31: ='Структура пр 2'!I36 -> 0 | AD31: ='Структура пр 2'!W36 -> 0 | AE31: ='Структура пр 2'!X36 -> 0 | AF31: ='Структура пр 2'!AL36 -> 0 | AG31: ='Структура пр 2'!AM36 -> 0 | AH31: ='Структура пр 2'!BA36 -> 0 | AI31: ='Структура пр 2'!BB36 -> 0 | AJ31: =AH31+AF31+AD31+AB31 -> 0 | AK31: ='Структура пр 2'!BB38 -> 0 | AL31: ='Структура пр 2'!M36 -> 0 | AM31: ='Структура пр 2'!AB36 -> 0 | AN31: ='Структура пр 2'!AQ36 -> 0 | AO31: ='Структура пр 2'!BF36 -> 0 | AP31: =AO31+AN31+AM31+AL31 -> 0 | AQ31: =R31/1000*0.123 -> 1.2177 | AR31: =S31/1000*0.123 -> 1.655088 | AS31: =T31/1000*0.123 -> 1.863081 | AT31: =U31/1000*0.123 -> 1.862343 | AU31: =V31/1000*0.123 -> 6.598212 | AV31: =W31*1.16 -> 15.68668 | AW31: =X31*1.16 -> 2.41976 | AX31: =Y31*1.16 -> 1.81656 | AY31: =Z31*1.16 -> 11.47356 | AZ31: =AA31*1.16 -> 31.39656 | BA31: =AQ31+AV31 -> 16.90438 | BB31: =AR31+AW31 -> 4.074848 | BC31: =AS31+AX31 -> 3.679641 | BD31: =AT31+AY31 -> 13.335903 | BE31: =AU31+AZ31 -> 37.994772 | BF31: – на хозяйственно-бытовые нужды
A32: В разрезе видов выпускаемой продукции (основной и побочной) | C32: =V32 -> 5113953 | F32: =AA32 -> 32.25 | R32: ='Структура пр 2'!B37 -> 943780 | S32: ='Структура пр 2'!Q37 -> 1282804 | T32: ='Структура пр 2'!AF37 -> 1444004 | U32: ='Структура пр 2'!AU37 -> 1443365 | V32: =U32+T32+S32+R32 -> 5113953 | W32: =W29+W31 -> 14.819 | X32: =X29+X31 -> 3.382 | Y32: =Y29+Y31 -> 2.862 | Z32: =Z29+Z31 -> 11.187 | AA32: =Z32+Y32+X32+W32 -> 32.25 | AB32: ='Структура пр 2'!H37 -> 0 | AC32: ='Структура пр 2'!I37 -> 0 | AD32: ='Структура пр 2'!W37 -> 0 | AE32: ='Структура пр 2'!X37 -> 0 | AF32: ='Структура пр 2'!AL37 -> 0 | AG32: ='Структура пр 2'!AM37 -> 0 | AH32: ='Структура пр 2'!BA37 -> 0 | AI32: ='Структура пр 2'!BB37 -> 0 | AJ32: =AH32+AF32+AD32+AB32 -> 0 | AK32: ='Структура пр 2'!BB45 -> 0 | AL32: ='Структура пр 2'!M37 -> 0 | AM32: ='Структура пр 2'!AB37 -> 0 | AN32: ='Структура пр 2'!AQ37 -> 0 | AO32: ='Структура пр 2'!BF37 -> 0 | AP32: =AO32+AN32+AM32+AL32 -> 0 | AQ32: =R32/1000*0.123 -> 116.08494 | AR32: =S32/1000*0.123 -> 157.78489 | AS32: =T32/1000*0.123 -> 177.61249 | AT32: =U32/1000*0.123 -> 177.5339 | AU32: =V32/1000*0.123 -> 629.01622 | AV32: =W32*1.16 -> 17.19004 | AW32: =X32*1.16 -> 3.92312 | AX32: =Y32*1.16 -> 3.31992 | AY32: =Z32*1.16 -> 12.97692 | AZ32: =AA32*1.16 -> 37.41 | BA32: =AQ32+AV32 -> 133.27498 | BB32: =AR32+AW32 -> 161.70801 | BC32: =AS32+AX32 -> 180.93241 | BD32: =AT32+AY32 -> 190.51082 | BE32: =AU32+AZ32 -> 666.42622 | BF32: В разрезе видов выпускаемой продукции (основной и побочной)
A33: 1. Продукция (услуга): труба ХВС, фитинги ХВС и ГВС, канализационные трубы и фитинги, тёплый пол | C33: =V33 -> 5210438 | R33: ='Структура пр 2'!B39+'Структура пр 2'!B40+'Структура пр 2'!B41+'Структура пр 2'!B42+'Структура пр 2'!B43 -> 1279578 | S33: ='Структура пр 2'!Q39+'Структура пр 2'!Q40+'Структура пр 2'!Q41+'Структура пр 2'!Q42+'Структура пр 2'!Q43 -> 1323899 | T33: ='Структура пр 2'!AF39+'Структура пр 2'!AF40+'Структура пр 2'!AF41+'Структура пр 2'!AF42+'Структура пр 2'!AF43 -> 1365204 | U33: ='Структура пр 2'!AU39+'Структура пр 2'!AU40+'Структура пр 2'!AU41+'Структура пр 2'!AU42+'Структура пр 2'!AU43 -> 1241757 | V33: =U33+T33+S33+R33 -> 5210438 | AA33: =Z33+Y33+X33+W33 -> 0 | AJ33: =AH33+AF33+AD33+AB33 -> 0 | AK33: ='Структура пр 2'!BB46 -> 0 | AP33: =AO33+AN33+AM33+AL33 -> 0 | AU33: =V33/1000*0.123 -> 640.88387 | AZ33: =AA33*1.16 -> 0 | BE33: =AU33+AZ33 -> 640.88387
A38: Энергетический баланс предприятия
O39: Таблица 3
A40: Структура параметров баланса | C40: Электр энергияси | E40: Тепловая энергия | F40: Газ | G40: Мазут | H40: Уголь | J40: Нефтепродукты | O40: Вода | P40: Примечание | R40: не удалят | AQ40: 20224год не трогат
C41: актив Р | D41: реактив Q | J41: Бензин | K41: Дизель | L41: Керосин | M41: ГСМ (Горюче-смазочные материалы) | N41: Прочее | R41: электр | W41: газ | AB41: ГСМ | AL41: Вода | AQ41: электр в т.у.т | AV41: газ в т.у.т | BA41: итого в т.у.т
AB42: Д/т | AC42: бензин | AD42: Д/т | AE42: бензин | AF42: Д/т | AG42: бензин | AH42: Д/т | AI42: бензин | AJ42: Д/т | AK42: бензин
E43: Гкал | F43: тыс. м | G43: тонна | H43: тонна | J43: тонна | O43: м³ | R43: 1 | S43: 2 | T43: 3 | U43: 4 | V43: год | W43: 1 | X43: 2 | Y43: 3 | Z43: 4 | AA43: год | AB43: 1 | AD43: 2 | AF43: 3 | AH43: 4 | AJ43: год | AL43: 1 | AM43: 2 | AN43: 3 | AO43: 4 | AP43: год | AQ43: 1 | AR43: 2 | AS43: 3 | AT43: 4 | AU43: год | AV43: 1 | AW43: 2 | AX43: 3 | AY43: 4 | AZ43: год | BA43: 1 | BB43: 2 | BC43: 3 | BD43: 4 | BE43: год
A44: Установленная электрическая мощность | C44: =V44 -> 4950000 | D44: ='Узел учета '!D5 -> 1825000 | R44: ='Структура пр 2'!B52 -> 1200000 | S44: ='Структура пр 2'!Q52 -> 1200000 | T44: ='Структура пр 2'!AF52 -> 1200000 | U44: ='Структура пр 2'!AU52 -> 1350000 | V44: =U44+T44+S44+R44 -> 4950000 | W44: ='Структура пр 2'!E52 -> 0 | X44: ='Структура пр 2'!T52 -> 0 | Y44: ='Структура пр 2'!AI52 -> 0 | Z44: ='Структура пр 2'!AX52 -> 0 | AA44: =Z44+Y44+X44+W44 -> 0 | AB44: ='Структура пр 2'!H52 -> 0 | AC44: ='Структура пр 2'!I52 -> 0 | AD44: ='Структура пр 2'!W52 -> 0 | AE44: ='Структура пр 2'!X52 -> 0 | AF44: ='Структура пр 2'!AL52 -> 0 | AG44: ='Структура пр 2'!AM52 -> 0 | AH44: ='Структура пр 2'!AL52 -> 0 | AI44: ='Структура пр 2'!AM52 -> 0 | AJ44: =AH44+AF44+AD44+AB44 -> 0 | AK44: ='Структура пр 2'!BB57 -> 0 | AL44: ='Структура пр 2'!M52 -> 0 | AM44: ='Структура пр 2'!AB52 -> 0 | AN44: ='Структура пр 2'!AQ52 -> 0 | AO44: ='Структура пр 2'!BF52 -> 0 | AP44: =AO44+AN44+AM44+AL44 -> 0 | AQ44: =R44/1000*0.123 -> 147.6 | AR44: =S44/1000*0.123 -> 147.6 | AS44: =T44/1000*0.123 -> 147.6 | AT44: =U44/1000*0.123 -> 166.05 | AU44: =V44/1000*0.123 -> 608.85 | AV44: =W44*1.16 -> 0 | AW44: =X44*1.16 -> 0 | AX44: =Y44*1.16 -> 0 | AY44: =Z44*1.16 -> 0 | AZ44: =AA44*1.16 -> 0 | BA44: =AQ44+AV44 -> 147.6 | BB44: =AR44+AW44 -> 147.6 | BC44: =AS44+AX44 -> 147.6 | BD44: =AT44+AY44 -> 166.05 | BE44: =AU44+AZ44 -> 608.85 | BF44: Установленная электрическая мощность
A45: Транзитным абониментам | R45: ='Структура пр 2'!B53 -> 0 | S45: ='Структура пр 2'!Q53 -> 0 | T45: ='Структура пр 2'!AF53 -> 0 | U45: ='Структура пр 2'!AU53 -> 0 | V45: =U45+T45+S45+R45 -> 0 | W45: ='Структура пр 2'!E53 -> 0 | X45: ='Структура пр 2'!T53 -> 0 | Y45: ='Структура пр 2'!AI53 -> 0 | Z45: ='Структура пр 2'!AX53 -> 0 | AA45: =Z45+Y45+X45+W45 -> 0 | AB45: ='Структура пр 2'!H53 -> 0 | AC45: ='Структура пр 2'!I53 -> 0 | AD45: ='Структура пр 2'!W53 -> 0 | AE45: ='Структура пр 2'!X53 -> 0 | AF45: ='Структура пр 2'!AL53 -> 0 | AG45: ='Структура пр 2'!AM53 -> 0 | AH45: ='Структура пр 2'!AL53 -> 0 | AI45: ='Структура пр 2'!AM53 -> 0 | AJ45: =AH45+AF45+AD45+AB45 -> 0 | AK45: ='Структура пр 2'!BB58 -> 0 | AL45: ='Структура пр 2'!M53 -> 0 | AM45: ='Структура пр 2'!AB53 -> 0 | AN45: ='Структура пр 2'!AQ53 -> 0 | AO45: ='Структура пр 2'!BF53 -> 0 | AP45: =AO45+AN45+AM45+AL45 -> 0 | AQ45: =R45/1000*0.123 -> 0 | AR45: =S45/1000*0.123 -> 0 | AS45: =T45/1000*0.123 -> 0 | AT45: =U45/1000*0.123 -> 0 | AU45: =V45/1000*0.123 -> 0 | AV45: =W45*1.16 -> 0 | AW45: =X45*1.16 -> 0 | AX45: =Y45*1.16 -> 0 | AY45: =Z45*1.16 -> 0 | AZ45: =AA45*1.16 -> 0 | BA45: =AQ45+AV45 -> 0 | BB45: =AR45+AW45 -> 0 | BC45: =AS45+AX45 -> 0 | BD45: =AT45+AY45 -> 0 | BE45: =AU45+AZ45 -> 0 | BF45: Транзитным абониментам
A46: Общее потребление по предприятию | C46: =V46 -> 4868248 | F46: =AA46 -> 38.759 | R46: ='Структура пр 2'!B54 -> 1156453 | S46: ='Структура пр 2'!Q54 -> 1038843 | T46: ='Структура пр 2'!AF54 -> 1293246 | U46: ='Структура пр 2'!AU54 -> 1379706 | V46: =U46+T46+S46+R46 -> 4868248 | W46: ='Структура пр 2'!E54 -> 22.078 | X46: ='Структура пр 2'!T54 -> 2.708 | Y46: ='Структура пр 2'!AI54 -> 2.171 | Z46: ='Структура пр 2'!AX54 -> 11.802 | AA46: =Z46+Y46+X46+W46 -> 38.759 | AB46: ='Структура пр 2'!H54 -> 0 | AC46: ='Структура пр 2'!I54 -> 0 | AD46: ='Структура пр 2'!W54 -> 0 | AE46: ='Структура пр 2'!X54 -> 0 | AF46: ='Структура пр 2'!AL54 -> 0 | AG46: ='Структура пр 2'!AM54 -> 0 | AH46: ='Структура пр 2'!AL54 -> 0 | AI46: ='Структура пр 2'!AM54 -> 0 | AJ46: =AH46+AF46+AD46+AB46 -> 0 | AK46: ='Структура пр 2'!BB59 -> 0 | AL46: ='Структура пр 2'!M54 -> 1238 | AM46: ='Структура пр 2'!AB54 -> 1849 | AN46: ='Структура пр 2'!AQ54 -> 1827 | AO46: ='Структура пр 2'!BF54 -> 2092 | AP46: =AO46+AN46+AM46+AL46 -> 7006 | AQ46: =R46/1000*0.123 -> 142.24372 | AR46: =S46/1000*0.123 -> 127.77769 | AS46: =T46/1000*0.123 -> 159.06926 | AT46: =U46/1000*0.123 -> 169.70384 | AU46: =V46/1000*0.123 -> 598.7945 | AV46: =W46*1.16 -> 25.61048 | AW46: =X46*1.16 -> 3.14128 | AX46: =Y46*1.16 -> 2.51836 | AY46: =Z46*1.16 -> 13.69032 | AZ46: =AA46*1.16 -> 44.96044 | BA46: =AQ46+AV46 -> 167.8542 | BB46: =AR46+AW46 -> 130.91897 | BC46: =AS46+AX46 -> 161.58762 | BD46: =AT46+AY46 -> 183.39416 | BE46: =AU46+AZ46 -> 643.75494 | BF46: Общее потребление по предприятию
A47: – на технологические нужды | C47: =V47 -> 3825344 | R47: ='Структура пр 2'!B55 -> 908711 | S47: ='Структура пр 2'!Q55 -> 816296 | T47: ='Структура пр 2'!AF55 -> 1016199 | U47: ='Структура пр 2'!AU55 -> 1084138 | V47: =U47+T47+S47+R47 -> 3825344 | W47: ='Структура пр 2'!E55 -> 0 | X47: ='Структура пр 2'!T55 -> 0 | Y47: ='Структура пр 2'!AI55 -> 0 | Z47: ='Структура пр 2'!AX55 -> 0 | AA47: =Z47+Y47+X47+W47 -> 0 | AB47: ='Структура пр 2'!H55 -> 0 | AC47: ='Структура пр 2'!I55 -> 0 | AD47: ='Структура пр 2'!W55 -> 0 | AE47: ='Структура пр 2'!X55 -> 0 | AF47: ='Структура пр 2'!AL55 -> 0 | AG47: ='Структура пр 2'!AM55 -> 0 | AH47: ='Структура пр 2'!AL55 -> 0 | AI47: ='Структура пр 2'!AM55 -> 0 | AJ47: =AH47+AF47+AD47+AB47 -> 0 | AK47: ='Структура пр 2'!BB60 -> 0 | AL47: ='Структура пр 2'!M55 -> 0 | AM47: ='Структура пр 2'!AB55 -> 0 | AN47: ='Структура пр 2'!AQ55 -> 0 | AO47: ='Структура пр 2'!BF55 -> 0 | AP47: =AO47+AN47+AM47+AL47 -> 0 | AQ47: =R47/1000*0.123 -> 111.77145 | AR47: =S47/1000*0.123 -> 100.40441 | AS47: =T47/1000*0.123 -> 124.99248 | AT47: =U47/1000*0.123 -> 133.34897 | AU47: =V47/1000*0.123 -> 470.51731 | AV47: =W47*1.16 -> 0 | AW47: =X47*1.16 -> 0 | AX47: =Y47*1.16 -> 0 | AY47: =Z47*1.16 -> 0 | AZ47: =AA47*1.16 -> 0 | BA47: =AQ47+AV47 -> 111.77145 | BB47: =AR47+AW47 -> 100.40441 | BC47: =AS47+AX47 -> 124.99248 | BD47: =AT47+AY47 -> 133.34897 | BE47: =AU47+AZ47 -> 470.51731 | BF47: – на технологические нужды
...

Sheet Динамика ср
A1: 2022 г.Сравнителные показатели динамика расходов энергии
M2: Таблица 5
A3: ЭНЕРГОРЕСУРСЫ | C3: Электроэнергия, кВт·ч | H3: Тепловая энергия, Гкал | M3: Природный газ, тыс. м³
A4: Квартал | C4: I | D4: II | E4: III | F4: IV | G4: йил | H4: I | I4: II | J4: III | K4: IV | L4: йил | M4: I | N4: II | O4: III | P4: IV | Q4: йил
A5: Основной вид продукции (услуги) | B5: удельный расход за прошлый год (факт) | C5: 0 | D5: 0 | E5: 0 | F5: 0 | G5: 0 | H5: 0 | I5: 0 | J5: 0 | K5: 0 | L5: 0 | M5: 0 | N5: 0 | O5: 0 | P5: 0 | Q5: 0
B6: удельный расход за отчётный год (факт) | C6: ='Структура пр 2'!B15:C15 -> 0 | D6: ='Структура пр 2'!Q15 -> 890249 | E6: ='Структура пр 2'!AF15 -> 1078949 | F6: ='Структура пр 2'!AU15 -> 1014849 | G6: =F6+E6+D6+C6 -> 2984047 | H6: 0 | I6: 0 | J6: 0 | K6: 0 | L6: 0 | M6: ='Структура пр 2'!D15 -> 0 | N6: ='Структура пр 2'!T15 -> 0 | O6: ='Структура пр 2'!AI15 -> 0 | P6: ='Структура пр 2'!AW15 -> 0 | Q6: =P6+O6+N6+M6 -> 0
A7: Дополнительная продукция (услуга) | B7: удельный расход за прошлый год (факт) | H7: 0 | I7: 0 | J7: 0 | K7: 0 | L7: 0
B8: удельный расход за отчётный год (факт) | H8: 0 | I8: 0 | J8: 0 | K8: 0 | L8: 0
A9: Технологическое потребление | B9: удельный расход за прошлый год (факт) | C9: 0 | D9: 0 | E9: 0 | F9: 0 | G9: 0 | H9: 0 | I9: 0 | J9: 0 | K9: 0 | L9: 0 | M9: 0 | N9: 0 | O9: 0 | P9: 0 | Q9: 0
B10: удельный расход за отчётный год (факт) | C10: ='Структура пр 2'!B11 -> 795615 | D10: ='Структура пр 2'!Q11 -> 721299 | E10: ='Структура пр 2'!AF11 -> 874187 | F10: ='Структура пр 2'!AU11 -> 822252 | G10: =F10+E10+D10+C10 -> 3213353 | H10: 0 | I10: 0 | J10: 0 | K10: 0 | L10: 0 | M10: ='Структура пр 2'!E11 -> 0 | N10: ='Структура пр 2'!T11 -> 0 | O10: ='Структура пр 2'!AI11 -> 0 | P10: ='Структура пр 2'!AX11 -> 0 | Q10: =P10+O10+N10+M10 -> 0
A11: Изменение удельного энергопотребления в отчётном году по сравнению с фактическим удельным потреблением прошлого года, % (увеличение или снижение)* | C11: 0 | D11: 0 | E11: 0 | F11: 0 | G11: 0 | H11: 0 | I11: 0 | J11: 0 | K11: 0 | L11: 0 | M11: 0 | N11: 0 | O11: 0 | P11: 0 | Q11: 0
A12: Хозяйственно-бытовое потребление (тыс. кВт·ч / Гкал / тыс. м³) | C12: ='Структура пр 2'!B14/1000 -> 10.301 | D12: ='Структура пр 2'!Q14/1000 -> 9.339 | E12: ='Структура пр 2'!AF14/1000 -> 11.318 | F12: ='Структура пр 2'!AU14/1000 -> 10.646 | G12: =F12+E12+D12+C12 -> 41.604 | H12: 0 | I12: 0 | J12: 0 | K12: 0 | L12: 0 | M12: ='Структура пр 2'!E14 -> 14.371 | N12: ='Структура пр 2'!T14 -> 2.44 | O12: ='Структура пр 2'!AI14 -> 1.191 | P12: ='Структура пр 2'!AX14 -> 7.725 | Q12: =P12+O12+N12+M12 -> 25.727
A13: Общее потребление энергоресурсов (тыс. кВт·ч / Гкал / тыс. м³) | C13: ='Структура пр 2'!B10/1000 -> 1012.524 | D13: ='Структура пр 2'!Q10/1000 -> 917.947 | E13: ='Структура пр 2'!AF10/1000 -> 1112.517 | F13: ='Структура пр 2'!AU10/1000 -> 1046.423 | G13: =F13+E13+D13+C13 -> 4089.411 | H13: 0 | I13: 0 | J13: 0 | K13: 0 | L13: 0 | M13: ='Структура пр 2'!E10 -> 15.667 | N13: ='Структура пр 2'!T10 -> 3.736 | O13: ='Структура пр 2'!AI10 -> 2.487 | P13: ='Структура пр 2'!AX10 -> 9.021 | Q13: =P13+O13+N13+M13 -> 30.911
A14: Нормативное потребление, % э-э (8.6 кВт*ч/м2) газ (3.4 м3/м2) | C14: ='Расход на ед.п'!$T$16*100 -> 66.860465 | D14: ='Расход на ед.п'!$T$16*100 -> 66.860465 | E14: ='Расход на ед.п'!$T$16*100 -> 66.860465 | F14: ='Расход на ед.п'!$T$16*100 -> 66.860465 | G14: ='Расход на ед.п'!$T$16*100 -> 66.860465 | Q14: 59.6 % снижение
A18: 2023 г.Сравнителные показатели динамика расходов энергии
M19: Таблица 5
A20: ЭНЕРГОРЕСУРСЫ | C20: Электроэнергия, кВт·ч | H20: Тепловая энергия, Гкал | M20: Природный газ, тыс. м³
A21: Квартал | C21: I | D21: II | E21: III | F21: IV | G21: йил | H21: I | I21: II | J21: III | K21: IV | L21: йил | M21: I | N21: II | O21: III | P21: IV | Q21: йил
A22: Основной вид продукции (услуги) | B22: удельный расход за прошлый год (факт) | C22: =C6 -> 0 | D22: =D6 -> 890249 | E22: =E6 -> 1078949 | F22: =F6 -> 1014849 | G22: =G6 -> 2984047 | H22: =H6 -> 0 | I22: =I6 -> 0 | J22: =J6 -> 0 | ... Q22: =Q6 -> 0
B23: удельный расход за отчётный год (факт) | C23: ='Структура пр 2'!B37 -> 943780 | D23: ='Структура пр 2'!Q37 -> 1282804 | E23: ='Структура пр 2'!AF37 -> 1444004 | F23: ='Структура пр 2'!AU37 -> 1443365 | G23: =F23+E23+D23+C23 -> 5113953 | M23: ='[1]Структура пр 2'!D37 -> 0 | N23: ='Структура пр 2'!S37 -> 0 | O23: ='Структура пр 2'!AH37 -> 0 | P23: ='Структура пр 2'!AW37 -> 0 | Q23: =P23+O23+N23+M23 -> 0
A24: Дополнительная продукция (услуга) | B24: удельный расход за прошлый год (факт)
B25: удельный расход за отчётный год (факт)
A26: Технологическое потребление | B26: удельный расход за прошлый год (факт) | C26: =C10 -> 795615 | D26: =D10 -> 721299 | E26: =E10 -> 874187 | F26: =F10 -> 822252 | G26: =G10 -> 3213353 | H26: =H10 -> 0 | I26: =I10 -> 0 | J26: =J10 -> 0 | ... Q26: =Q10 -> 0
B27: удельный расход за отчётный год (факт) | C27: ='Структура пр 2'!B33 -> 764671 | D27: ='Структура пр 2'!Q33 -> 1039355 | E27: ='Структура пр 2'!AF33 -> 1169963 | F27: ='Структура пр 2'!AU33 -> 1169445 | G27: =F27+E27+D27+C27 -> 4143434 | M27: ='Структура пр 2'!E33 -> 0 | N27: ='Структура пр 2'!T33 -> 0 | O27: ='Структура пр 2'!AI33 -> 0 | P27: ='Структура пр 2'!AX33 -> 0 | Q27: =P27+O27+N27+M27 -> 0
A28: Изменение удельного энергопотребления в отчётном году по сравнению с фактическим удельным потреблением прошлого года, % (увеличение или снижение)* | C28: 24.5% увеличение | D28: 35.9% увеличение | E28: 12.3% снижение | F28: 18.4 % снижение | G28: 5.1 % увеличение | M28: 6.9 % снижение | N28: 43.7 % увеличение | O28: 15.9 % увеличение
A29: Хозяйственно-бытовое потребление (тыс. кВт·ч / Гкал / тыс. м³) | C29: ='Структура пр 2'!B36/1000 -> 9.9 | D29: ='Структура пр 2'!Q36/1000 -> 13.456 | E29: ='Структура пр 2'!AF36/1000 -> 15.147 | F29: ='Структура пр 2'!AU36/1000 -> 15.141 | G29: =F29+E29+D29+C29 -> 53.644 | M29: ='Структура пр 2'!E36 -> 13.523 | N29: ='Структура пр 2'!T36 -> 2.086 | O29: ='Структура пр 2'!AI36 -> 1.566 | P29: ='Структура пр 2'!AX36 -> 9.891 | Q29: =P29+O29+N29+M29 -> 27.066
A30: Общее потребление энергоресурсов (тыс. кВт·ч / Гкал / тыс. м³) | C30: ='Структура пр 2'!B32/1000 -> 973.143 | D30: ='Структура пр 2'!Q32/1000 -> 1322.714 | E30: ='Структура пр 2'!AF32/1000 -> 1488.93 | F30: ='Структура пр 2'!AU32/1000 -> 1488.271 | G30: =F30+E30+D30+C30 -> 5273.058 | M30: ='Структура пр 2'!E32 -> 14.0819 | N30: ='Структура пр 2'!T32 -> 3.382 | O30: ='Структура пр 2'!AI32 -> 2.862 | P30: ='Структура пр 2'!AX32 -> 11.187 | Q30: =P30+O30+N30+M30 -> 31.5129
A31: Нормативное потребление, % э-э (8.6 кВт*ч/м2) газ (3.4 м3/м2) | C31: ='Расход на ед.п'!T17*100 -> 76.627907 | D31: ='Расход на ед.п'!T17*100 -> 76.627907 | E31: ='Расход на ед.п'!T17*100 -> 76.627907 | F31: ='Расход на ед.п'!T17*100 -> 76.627907 | G31: ='Расход на ед.п'!T17*100 -> 76.627907
A35: 2024 г.Сравнителные показатели динамика расходов энергии
M36: Таблица 5
A37: ЭНЕРГОРЕСУРСЫ | C37: Электроэнергия, кВт·ч | H37: Тепловая энергия, Гкал | M37: Природный газ, тыс. м³ | U37: кВт/м2 | W37: м3/м2
A38: Квартал | C38: I | D38: II | E38: III | F38: IV | G38: йил | H38: I | I38: II | J38: III | K38: IV | L38: йил | M38: I | N38: II | O38: III | P38: IV | Q38: йил | T38: 8.6 | U38: 5.75 | V38: =U38/T38 -> 0.66860465 | W38: 1.383 | X38: 3.4 | Y38: =W38/X38 -> 0.40676471
A39: Основной вид продукции (услуги) | B39: удельный расход за прошлый год (факт) | C39: =C23 -> 943780 | D39: =D23 -> 1282804 | E39: =E23 -> 1444004 | F39: =F23 -> 1443365 | G39: =G23 -> 5113953 | H39: =H23 -> 0 | I39: =I23 -> 0 | J39: =J23 -> 0 | ... Q39: =Q23 -> 0 | T39: 8.6 | U39: 6.59 | V39: =U39/T39 -> 0.76627907 | W39: 1.949 | X39: 3.4 | Y39: =W39/X39 -> 0.57323529
B40: удельный расход за отчётный год (факт) | C40: ='Структура пр 2'!B59 -> 1121559 | D40: ='Структура пр 2'!Q59 -> 1007498 | E40: ='Структура пр 2'!AF59 -> 1254224 | F40: ='Структура пр 2'!AU59 -> 1338076 | G40: =F40+E40+D40+C40 -> 4721357 | M40: ='Структура пр 2'!D59 -> 0 | N40: ='Структура пр 2'!S59 -> 0 | O40: ='Структура пр 2'!AH59 -> 0 | P40: ='Структура пр 2'!AW59 -> 0 | Q40: =P40+O40+N40+M40 -> 0 | T40: 8.6 | U40: 8.12 | V40: =U40/T40 -> 0.94418605 | W40: 3.413 | X40: 3.4 | Y40: =W40/X40 -> 1.0038235
A41: Дополнительная продукция (услуга) | B41: удельный расход за прошлый год (факт)
B42: удельный расход за отчётный год (факт)
A43: Технологическое потребление | B43: удельный расход за прошлый год (факт) | C43: =C27 -> 764671 | D43: =D27 -> 1039355 | E43: =E27 -> 1169963 | F43: =F27 -> 1169445 | G43: =G27 -> 4143434 | H43: =H27 -> 0 | I43: =I27 -> 0 | J43: =J27 -> 0 | ... Q43: =Q27 -> 0
B44: удельный расход за отчётный год (факт) | C44: ='Структура пр 2'!B55 -> 908711 | D44: ='Структура пр 2'!Q55 -> 816296 | E44: ='Структура пр 2'!AF55 -> 1016199 | F44: ='Структура пр 2'!AU55 -> 1084138 | G44: =F44+E44+D44+C44 -> 3825344 | M44: ='Структура пр 2'!E55 -> 0 | N44: ='Структура пр 2'!T55 -> 0 | O44: ='Структура пр 2'!AI55 -> 0 | P44: ='Структура пр 2'!AX55 -> 0 | Q44: =P44+O44+N44+M44 -> 0
A45: Изменение удельного энергопотребления в отчётном году по сравнению с фактическим удельным потреблением прошлого года, % (увеличение или снижение)* | C45: 15.8 % снижение | D45: 33.6 % снижение | E45: 21 % снижение | F45: 69.2 % снижение | G45: 33.4 % снижение | M45: 9.3 % увеличение | N45: 18.6 % снижение | O45: 36.6 % снижение | P45: 23.8 % снижение | Q45: 15.6 % снижение
A46: Хозяйственно-бытовое потребление (тыс. кВт·ч / Гкал / тыс. м³) | C46: ='Структура пр 2'!B58/1000 -> 11.765 | D46: ='Структура пр 2'!Q58/1000 -> 10.568 | E46: ='Структура пр 2'!AF58/1000 -> 13.157 | F46: ='Структура пр 2'!AU58/1000 -> 14.036 | G46: =F46+E46+D46+C46 -> 49.526 | M46: ='Структура пр 2'!E58 -> 20.782 | N46: ='Структура пр 2'!T58 -> 1.412 | O46: ='Структура пр 2'!AI58 -> 0.875 | P46: ='Структура пр 2'!AX58 -> 10.506 | Q46: =P46+O46+N46+M46 -> 33.575
...

Sheet мазут,уголь 5 
A1: Динамика изменения удельных показателей в 2022 году
A2: ЭНЕРГИЯ РЕСУРСЛАРИ | C2: Мазут, т | H2: Нефтепродукты, т (бензин) | M2: Уголь, т | R2: Нефтепродукты, т (дизель)
A3: Квартал | C3: I | D3: II | E3: III | F3: IV | G3: йил | H3: I | I3: II | J3: III | K3: IV | L3: йил | M3: I | N3: II | O3: III | P3: IV | Q3: йил | R3: I | S3: II | T3: III | U3: IV | V3: йил
A4: Основной вид продукции (услуги) | B4: удельный расход за прошлый год (факт)
B5: удельный расход за отчётный год (факт)
A6: Дополнительная продукция (услуга) | B6: удельный расход за прошлый год (факт)
A7: Технологическое потребление | B7: удельный расход за отчётный год (факт)
B8: удельный расход за прошлый год (факт)
A9: Изменение удельного энергопотребления в отчётном году по сравнению с фактическим удельным потреблением прошлого года, % (увеличение или снижение*
A10: Хозяйственно-бытовое потребление (тыс. кВт·ч / Гкал / тыс. м³)
A11: Общее потребление энергоресурсов (тыс. кВт·ч / Гкал / тыс. м³) | R11: ='[2]Структура пр 2 '!I10 -> 0 | S11: ='[2]Структура пр 2 '!X10 -> 0 | T11: ='[2]Структура пр 2 '!AM10 -> 0 | U11: ='[2]Структура пр 2 '!BB10 -> 0 | V11: =U11+T11+S11+R11 -> 0
A12: Нормативное потребление, %
A16: Динамика изменения удельных показателей в 2023 году
A17: ЭНЕРГИЯ РЕСУРСЛАРИ | C17: Мазут, т | H17: Нефтепродукты, т (бензин) | M17: Уголь, т | R17: Нефтепродукты, т (дизель)
A18: Квартал | C18: I | D18: II | E18: III | F18: IV | G18: йил | H18: I | I18: II | J18: III | K18: IV | L18: йил | M18: I | N18: II | O18: III | P18: IV | Q18: йил | R18: I | S18: II | T18: III | U18: IV | V18: йил
A19: Основной вид продукции (услуги) | B19: удельный расход за прошлый год (факт)
B20: удельный расход за отчётный год (факт)
A21: Дополнительная продукция (услуга) | B21: удельный расход за прошлый год (факт)
A22: Технологическое потребление | B22: удельный расход за отчётный год (факт)
B23: удельный расход за прошлый год (факт)
A24: Изменение удельного энергопотребления в отчётном году по сравнению с фактическим удельным потреблением прошлого года, % (увеличение или снижение*
A25: Хозяйственно-бытовое потребление (тыс. кВт·ч / Гкал / тыс. м³)
